Workbook

Sheet IN_MACRO
A1: ۱. فرضیات کلان اقتصادی | B1: لایه ورودی
A2: تمام مفروضات اقتصاد کلان در این شیت وارد می‌شود؛ هیچ فرمولی مجاز نیست. واحد پول مدل: میلیون ریال.
A7: دوره (t) | D7: 0 | E7: 1 | F7: 2 | G7: 3 | H7: 4 | I7: 5 | J7: 6 | K7: 7 | L7: 8 | M7: 9 | N7: 10 | O7: 11 | P7: 12
A8: سال تقویمی | D8: 2026 | E8: 2027 | F8: 2028 | G8: 2029 | H8: 2030 | I8: 2031 | J8: 2032 | K8: 2033 | L8: 2034 | M8: 2035 | N8: 2036 | O8: 2037 | P8: 2038
A9: الف) پارامترهای کنترلی و ثابت مدل
A10: سال شروع مدل (میلادی) | B10: MAC.start_year | C10: سال | D10: 2026
A11: افق مدل (سال بهره‌برداری) | B11: MAC.horizon | C11: سال | D11: 12
A12: شاخص سال آغاز بهره‌برداری (t) | B12: MAC.ops_start | C12: شاخص | D12: 1
A13: شاخص سال پایان دوره ساخت (t) | B13: MAC.constr_end | C13: شاخص | D13: 1
A14: نرخ مالیات بر درآمد | B14: MAC.tax | C14: درصد | D14: 0.2
A15: صرف ریسک بازار سهام (ERP) | B15: MAC.erp | C15: درصد | D15: 0.06
A16: بتای سهام | B16: MAC.beta | C16: ضریب | D16: 1.15
A17: صرف ریسک کشور (CRP) | B17: MAC.crp | C17: درصد | D17: 0.04
A18: نرخ رشد دائمی اسمی | B18: MAC.g_term | C18: درصد | D18: 0.18
A19: روش ارزش پایانی (1=گوردون/2=ضریب خروج) | B19: MAC.tv_method | C19: 1/2 | D19: 2
A20: ضریب خروج (EV/EBITDA) | B20: MAC.exit_mult | C20: ضریب | D20: 6
A22: ب) مسیرهای سالانهٔ اقتصاد کلان (ورودی عددی)
A23: شاخص دوره (t) | B23: MAC.t | C23: شاخص | D23: 0 | E23: 1 | F23: 2 | G23: 3 | H23: 4 | I23: 5 | J23: 6 | K23: 7 | L23: 8 | M23: 9 | N23: 10 | O23: 11 | P23: 12
A24: سال تقویمی | B24: MAC.year | C24: سال | D24: 2026 | E24: 2027 | F24: 2028 | G24: 2029 | H24: 2030 | I24: 2031 | J24: 2032 | K24: 2033 | L24: 2034 | M24: 2035 | N24: 2036 | O24: 2037 | P24: 2038
A25: نرخ تورم عمومی | B25: MAC.infl | C25: درصد | D25: 0.25 | E25: 0.25 | F25: 0.23 | G25: 0.22 | H25: 0.2 | I25: 0.2 | J25: 0.18 | K25: 0.18 | L25: 0.16 | M25: 0.16 | N25: 0.15 | O25: 0.15 | P25: 0.15
A26: نرخ رشد دستمزد | B26: MAC.wage | C26: درصد | D26: 0.27 | E26: 0.26 | F26: 0.25 | G26: 0.23 | H26: 0.22 | I26: 0.21 | J26: 0.2 | K26: 0.19 | L26: 0.18 | M26: 0.17 | N26: 0.17 | O26: 0.16 | P26: 0.16
A27: نرخ رشد قیمت حامل‌های انرژی | B27: MAC.energy | C27: درصد | D27: 0.3 | E27: 0.28 | F27: 0.26 | G27: 0.25 | H27: 0.23 | I27: 0.22 | J27: 0.21 | K27: 0.2 | L27: 0.2 | M27: 0.19 | N27: 0.18 | O27: 0.18 | P27: 0.18
A28: نرخ ارز (ریال به ازای دلار) | B28: MAC.fx | C28: ریال/دلار | D28: 500000 | E28: 620000 | F28: 760000 | G28: 930000 | H28: 1120000 | I28: 1340000 | J28: 1590000 | K28: 1870000 | L28: 2180000 | M28: 2510000 | N28: 2860000 | O28: 3230000 | P28: 3610000
A29: قیمت جهانی سرب (LME) | B29: MAC.lme | C29: دلار/تن | D29: 2100 | E29: 2150 | F29: 2200 | G29: 2250 | H29: 2250 | I29: 2300 | J29: 2300 | K29: 2350 | L29: 2350 | M29: 2400 | N29: 2400 | O29: 2450 | P29: 2450
A30: نرخ سود بدون ریسک اسمی | B30: MAC.rf | C30: درصد | D30: 0.24 | E30: 0.24 | F30: 0.23 | G30: 0.23 | H30: 0.22 | I30: 0.22 | J30: 0.21 | K30: 0.21 | L30: 0.2 | M30: 0.2 | N30: 0.2 | O30: 0.19 | P30: 0.19
A31: رشد GDP بخش هدف | B31: MAC.gdp | C31: درصد | D31: 0.03 | E31: 0.03 | F31: 0.035 | G31: 0.035 | H31: 0.04 | I31: 0.04 | J31: 0.04 | K31: 0.035 | L31: 0.035 | M31: 0.03 | N31: 0.03 | O31: 0.03 | P31: 0.03
A32: شاخص قیمت تولیدکننده | B32: MAC.ppi | C32: درصد | D32: 0.24 | E32: 0.24 | F32: 0.22 | G32: 0.21 | H32: 0.2 | I32: 0.19 | J32: 0.18 | K32: 0.18 | L32: 0.17 | M32: 0.16 | N32: 0.16 | O32: 0.15 | P32: 0.15
A33: پرچم دوره ساخت (1=بله) | B33: MAC.constr_flg | C33: 1/0 | D33: 1 | E33: 0 | F33: 0 | G33: 0 | H33: 0 | I33: 0 | J33: 0 | K33: 0 | L33: 0 | M33: 0 | N33: 0 | O33: 0 | P33: 0
A34: پرچم دوره بهره‌برداری (1=بله) | B34: MAC.ops_flg | C34: 1/0 | D34: 0 | E34: 1 | F34: 1 | G34: 1 | H34: 1 | I34: 1 | J34: 1 | K34: 1 | L34: 1 | M34: 1 | N34: 1 | O34: 1 | P34: 1
A36: ج) یادداشت‌های روش‌شناختی
A37: ۱. شاخص‌های قیمتی از سال پایه (t=0) ساخته می‌شوند؛ مقدار شاخص در t=0 برابر یک است.
A38: ۲. نرخ ارز به‌صورت «ریال به ازای هر دلار» وارد می‌شود و مسیر آن مبنای تعدیل اقلام ارزی است.
A39: ۳. قیمت جهانی سرب (LME) مبنای قیمت‌گذاری محصولاتِ پیوند‌خورده و نیز قیمت خرید باتری ضایعاتی است.
A40: ۴. روش ارزش پایانی: ۱=رشد دائمی (گوردون)، ۲=ضریب خروج (EV/EBITDA).

Sheet IN_TECH
A1: ۲. پارامترهای فنی خط تولید (ایستگاه‌های ۱ تا ۶) | B1: لایه ورودی
A2: ظرفیت اسمی و مؤثر، راندمان، ضایعات، زمان‌های توقف و محرک‌های تخصیص هزینه.
A7: الف) پارامترهای سطح کارخانه
A8: ظرفیت اسمی ورودی باتری | B8: TECH.cap_in | C8: تن/سال | D8: 40000
A9: روزهای کاری در سال | B9: TECH.days | C9: روز | D9: 330
A10: شیفت در روز | B10: TECH.shifts | C10: شیفت | D10: 3
A11: ساعت در شیفت | B11: TECH.hshift | C11: ساعت | D11: 8
A12: توقف برنامه‌ریزی‌شده | B12: TECH.dt_plan | C12: ساعت/سال | D12: 400
A13: توقف اضطراری | B13: TECH.dt_unplan | C13: ساعت/سال | D13: 300
A15: ب) عوامل بازیابی و تبدیل مواد
A16: عیار سرب در خمیر | B16: TECH.pb_paste | C16: درصد | D16: 0.72
A17: عیار سرب در قطعات فلزی | B17: TECH.pb_metal | C17: درصد | D17: 0.95
A18: راندمان سولفات‌زدایی | B18: TECH.desulf | C18: درصد | D18: 0.95
A19: راندمان کوره ذوب و احیا | B19: TECH.smelt | C19: درصد | D19: 0.97
A20: راندمان تصفیه نهایی | B20: TECH.refine | C20: درصد | D20: 0.99
A21: راندمان بازیابی پلی‌پروپیلن | B21: TECH.pp_rec | C21: درصد | D21: 0.92
A22: ضریب تولید سولفات سدیم | B22: TECH.na2so4 | C22: تن/تن | D22: 0.13
A23: سهم سرب خالص از سرب تصفیه‌شده | B23: TECH.sp_soft | C23: درصد | D23: 0.6
A24: سهم آلیاژ از سرب تصفیه‌شده | B24: TECH.sp_alloy | C24: درصد | D24: 0.4
A26: ج) ترکیب جرمی باتری ورودی (سهم از هر تن)
A27: خمیر سرب (Paste) | B27: TECH.sh_paste | C27: درصد | D27: 0.38
A28: قطعات فلزی سربی (Grid / Posts) | B28: TECH.sh_metal | C28: درصد | D28: 0.26
A29: پلی‌پروپیلن | B29: TECH.sh_pp | C29: درصد | D29: 0.09
A30: الکترولیت (اسید سولفوریک) | B30: TECH.sh_elec | C30: درصد | D30: 0.12
A31: جداکننده‌ها و سایر پسماند | B31: TECH.sh_res | C31: درصد | D31: 0.15
A33: د) جدول پارامترهای ایستگاه‌ها
A34: ایستگاه | D34: S1 | E34: S2 | F34: S3 | G34: S4 | H34: S5 | I34: S6
D35: پذیرش، تخلیه و جداسازی الکترولیت | E35: خردایش و جدایش هیدرودینامیکی | F35: سولفات‌زدایی خمیر سرب | G35: کوره ذوب و احیا | H35: تصفیه و آلیاژسازی | I35: شمش‌ریزی، بسته‌بندی و انبار
A36: ظرفیت اسمی (تن در سال) | B36: TECH.cap_yr | C36: تن/سال | D36: 42000 | E36: 42000 | F36: 17000 | G36: 27000 | H36: 21000 | I36: 30000
A37: ظرفیت اسمی (تن در ساعت) | B37: TECH.cap_hr | C37: تن/ساعت | D37: 6.5 | E37: 6.5 | F37: 2.6 | G37: 4.2 | H37: 3.3 | I37: 4.7
A38: نرخ دسترسی (Availability) | B38: TECH.avail | C38: درصد | D38: 0.92 | E38: 0.9 | F38: 0.93 | G38: 0.91 | H38: 0.94 | I38: 0.95
A39: راندمان ایستگاه | B39: TECH.yield | C39: درصد | D39: 0.98 | E39: 0.97 | F39: 0.95 | G39: 0.97 | H39: 0.99 | I39: 0.99
A40: نرخ ضایعات / دورریز | B40: TECH.scrap | C40: درصد | D40: 0.005 | E40: 0.01 | F40: 0.01 | G40: 0.005 | H40: 0.005 | I40: 0.01
A41: انرژی ویژه الکتریکی | B41: TECH.kwh | C41: kWh/تن | D41: 8 | E41: 22 | F41: 18 | G41: 95 | H41: 40 | I41: 12
A42: آب ویژه | B42: TECH.water | C42: m3/تن | D42: 0.1 | E42: 0.6 | F42: 1.2 | G42: 0.25 | H42: 0.2 | I42: 0.35
A44: ه‍) جدول محرک‌های تخصیص هزینه به ایستگاه‌ها
A45: محرک / ایستگاه | D45: S1 | E45: S2 | F45: S3 | G45: S4 | H45: S5 | I45: S6
D46: پذیرش، تخلیه و جداسازی الکترولیت | E46: خردایش و جدایش هیدرودینامیکی | F46: سولفات‌زدایی خمیر سرب | G46: کوره ذوب و احیا | H46: تصفیه و آلیاژسازی | I46: شمش‌ریزی، بسته‌بندی و انبار
A47: جریان مواد (تن/سال در ظرفیت طراحی) | B47: THROUGHPUT | C47: تن/سال | D47: 40000 | E47: 40000 | F47: 15200 | G47: 24840 | H47: 19700 | I47: 27900
A48: ساعت کار ماشین در سال (طراحی) | B48: MACHINE_HOURS | C48: ساعت/سال | D48: 6000 | E48: 7200 | F48: 6600 | G48: 7920 | H48: 6600 | I48: 7200
...

Sheet IN_SALES
A1: ۳. مفروضات قیمت‌گذاری و فروش | B1: لایه ورودی
A2: قیمت پایه، پیوند به قیمت جهانی، ترکیب سبد محصولات و سیاست‌های تخفیف و اعتبار.
A7: الف) ویژگی‌های سبد محصولات
A8: محصول | D8: P1 | E8: P2 | F8: P3 | G8: P4
D9: شمش سرب خالص (Pb 99.97) | E9: شمش آلیاژ سرب (Pb-Sb / Pb-Ca) | F9: گرانول پلی‌پروپیلن بازیافتی | G9: سولفات سدیم (محصول جانبی)
A10: قیمت پایه (سال پایه) | B10: SAL.price | C10: میلیون ریال/تن | D10: 1050 | E10: 1082 | F10: 325 | G10: 60
A11: پیوند قیمت به LME (1=بله/0=خیر) | B11: SAL.lme | C11: 1/0 | D11: 1 | E11: 1 | F11: 0 | G11: 0
A12: ضریب تعدیل نسبت به LME | B12: SAL.lmef | C12: ضریب | D12: 1 | E12: 1.03 | F12: 1 | G12: 1
A13: نرخ رشد سالانه قیمت داخلی | B13: SAL.esc | C13: درصد | D13: 0.2 | E13: 0.2 | F13: 0.22 | G13: 0.2
A14: سهم ارزی (صادراتی/شاخص ارز) | B14: SAL.fxsh | C14: درصد | D14: 0.35 | E14: 0.35 | F14: 0.1 | G14: 0.5
A15: نرخ تخفیف و برگشت از فروش | B15: SAL.disc | C15: درصد | D15: 0.015 | E15: 0.015 | F15: 0.03 | G15: 0.05
A16: ضریب تحقق فروش (فروش/تولید) | B16: SAL.real | C16: ضریب | D16: 1 | E16: 1 | F16: 0.98 | G16: 0.95
A18: ب) سیاست‌های اعتباری و فروش
A19: نرخ برگشت از فروش و ادعاهای کیفی | B19: SAL.disc_late | C19: درصد | D19: 0.01
A20: دوره بازنگری قیمت‌ها (ماه) | B20: SAL.price_rev | C20: ماه | D20: 3
A21: سهم فروش قراردادی بلندمدت | B21: SAL.contract | C21: درصد | D21: 0.4
A22: سهم فروش نقدی/فوری | B22: SAL.spot | C22: درصد | D22: 0.6
A24: توضیح: «سهم ارزی» نشان می‌دهد چه بخشی از درآمدِ هر محصول با نرخ ارز تعدیل می‌شود (مبنای تحلیل حساسیت ارزی).

Sheet IN_COST
A1: ۴. پارامترهای هزینه‌ای (FPC / OPC / DPC) | B1: لایه ورودی
A2: نرخ‌های واحد، پرسنل، مراکز هزینهٔ خدماتی و ماتریس اقلام هزینه با مبنای محاسبه و تخصیص.
A7: الف) نرخ‌ها و پارامترهای پایه
A8: سهم ارزی هزینه‌های متغیر | B8: CST.fx_var | C8: درصد | D8: 0.2
A9: سهم ارزی هزینه‌های ثابت | B9: CST.fx_fix | C9: درصد | D9: 0.05
A10: ماه‌های پرداخت حقوق در سال | B10: CST.months | C10: ماه | D10: 12
A11: ضریب مزایا، عیدی و سنوات | B11: CST.bonus | C11: ضریب | D11: 1.08
A13: ب) پرسنل (تعداد و حقوق ماهانهٔ پایه)
D14: کد طبقه | E14: تعداد نفر | F14: حقوق ماهانه | G14: واحد
A15: تولید مستقیم | B15: PAY1 | D15: 96 | E15: 250 | F15: نفر / میلیون ریال
A16: تولید غیرمستقیم | B16: PAY2 | D16: 24 | E16: 320 | F16: نفر / میلیون ریال
A17: نگهداری و تعمیرات | B17: PAY3 | D17: 18 | E17: 300 | F17: نفر / میلیون ریال
A18: اداری و مالی | B18: PAY4 | D18: 22 | E18: 380 | F18: نفر / میلیون ریال
A19: فروش و بازاریابی | B19: PAY5 | D19: 8 | E19: 350 | F19: نفر / میلیون ریال
A21: ج) مراکز هزینهٔ خدماتی
D22: نام مرکز | E22: محرک تخصیص | F22: هزینه سالانهٔ پایه | G22: رفتار | H22: ترتیب
A23: نگهداری و تعمیرات مرکزی | B23: SC1 | D23: نگهداری و تعمیرات مرکزی | E23: MACHINE_HOURS | F23: 300000 | G23: F | H23: 1
A24: منابع انسانی و خدمات پشتیبانی | B24: SC2 | D24: منابع انسانی و خدمات پشتیبانی | E24: HEADCOUNT | F24: 100000 | G24: F | H24: 2
A25: لجستیک و انبارداری | B25: SC3 | D25: لجستیک و انبارداری | E25: THROUGHPUT | F25: 150000 | G25: F | H25: 3
A26: تصفیه‌خانه و محیط‌زیست | B26: SC4 | D26: تصفیه‌خانه و محیط‌زیست | E26: WATER | F26: 250000 | G26: V | H26: 4
A27: آزمایشگاه و کنترل کیفیت | B27: SC5 | D27: آزمایشگاه و کنترل کیفیت | E27: THROUGHPUT | F27: 80000 | G27: V | H27: 5
A29: رفتار هزینه: V = متغیر (تابع حجم)، F = ثابت (سالانه).
A31: د) ماتریس اقلام هزینه (مبنای محاسبه، تعدیل و تخصیص)
D32: طبقه | E32: مبنای محاسبه | F32: پارامتر / مرجع | G32: شاخص تعدیل | H32: مبنای تخصیص | I32: رفتار
A33: باتری ضایعاتی (مواد اولیه اصلی) | B33: DPC-01 | C33: میلیون ریال/تن | D33: DPC | E33: SCRAP_LME | F33: 348 | G33: NONE | H33: THROUGHPUT | I33: V
A34: مواد مصرفی و واکنشگرها | B34: DPC-02 | C34: میلیون ریال/تن | D34: DPC | E34: PER_TON_BATT | F34: 15 | G34: CPI | H34: THROUGHPUT | I34: V
A35: دستمزد مستقیم تولید | B35: DPC-03 | C35: ─ | D35: DPC | E35: PAY | F35: PAY:1 | G35: WAGE | H35: HEADCOUNT | I35: V
A36: مواد بسته‌بندی | B36: DPC-04 | C36: میلیون ریال/تن | D36: DPC | E36: PER_TON_PROD | F36: 4 | G36: CPI | H36: THROUGHPUT | I36: V
A37: حمل‌ونقل ورودی مواد | B37: DPC-05 | C37: میلیون ریال/تن | D37: DPC | E37: PER_TON_BATT | F37: 6 | G37: CPI | H37: THROUGHPUT | I37: V
A38: انرژی الکتریکی فرآیندی | B38: DPC-06 | C38: میلیون ریال/kWh | D38: DPC | E38: PER_KWH | F38: 0.006 | G38: ENERGY | H38: MACHINE_HOURS | I38: V
A39: سوخت و مواد احیاکننده | B39: OPC-01 | C39: میلیون ریال/تن | D39: OPC | E39: PER_TON_BATT | F39: 12.5 | G39: ENERGY | H39: THROUGHPUT | I39: V
A40: آب و پساب | B40: OPC-02 | C40: میلیون ریال/m3 | D40: OPC | E40: PER_M3 | F40: 0.25 | G40: CPI | H40: WATER | I40: V
A41: دفع پسماند و لجن | B41: OPC-03 | C41: میلیون ریال/تن | D41: OPC | E41: PER_TON_BATT | F41: 7.5 | G41: CPI | H41: THROUGHPUT | I41: V
A42: نگهداری و تعمیرات متغیر | B42: OPC-04 | C42: میلیون ریال/تن | D42: OPC | E42: PER_TON_BATT | F42: 9 | G42: CPI | H42: MACHINE_HOURS | I42: V
A43: مرکز خدماتی: نگهداری و تعمیرات | B43: OPC-05 | C43: ─ | D43: OPC | E43: SRV | F43: SRV:1 | G43: CPI | H43: SRV | I43: F
A44: مرکز خدماتی: لجستیک و انبارداری | B44: OPC-06 | C44: ─ | D44: OPC | E44: SRV | F44: SRV:3 | G44: CPI | H44: SRV | I44: F
A45: مرکز خدماتی: تصفیه‌خانه | B45: OPC-07 | C45: ─ | D45: OPC | E45: SRV | F45: SRV:4 | G45: CPI | H45: SRV | I45: V
A46: مرکز خدماتی: آزمایشگاه و QC | B46: OPC-08 | C46: ─ | D46: OPC | E46: SRV | F46: SRV:5 | G46: CPI | H46: SRV | I46: V
A47: هزینه فروش، توزیع و کارمزد فروش | B47: OPC-09 | C47: درصد از درآمد | D47: OPC | E47: PCT_REV | F47: 0.012 | G47: NONE | H47: THROUGHPUT | I47: V
A48: استهلاک دارایی‌های ثابت | B48: FPC-01 | C48: ─ | D48: FPC | E48: DEP | F48: DEP | G48: NONE | H48: POWER | I48: F
...

Sheet IN_WC
A1: ۵. سیاست‌های سرمایه در گردش و چرخه نقدینگی | B1: لایه ورودی
A2: روزهای موجودی، دریافتنی و پرداختنی برای محاسبهٔ چرخهٔ تبدیل نقد (CCC).
A7: الف) دوره‌های سرمایه در گردش (روز)
A8: موجودی مواد اولیه (باتری ضایعاتی) | B8: WC.dio_rm | C8: روز | D8: 25
A9: موجودی کالای در جریان ساخت | B9: WC.dio_wip | C9: روز | D9: 8
A10: موجودی محصول نهایی | B10: WC.dio_fg | C10: روز | D10: 15
A11: موجودی مواد مصرفی و قطعات یدکی | B11: WC.dio_cons | C11: روز | D11: 30
A12: دوره وصول مطالبات (DSO) | B12: WC.dso | C12: روز | D12: 45
A13: دوره پرداخت بدهی‌ها (DPO) | B13: WC.dpo | C13: روز | D13: 40
A14: دوره پرداخت مالیات | B14: WC.dpo_tax | C14: روز | D14: 30
A15: ذخیره نقدی عملیاتی (روز هزینه نقدی) | B15: WC.cashdays | C15: روز | D15: 15
A17: ب) سیاست‌های تأمین مالی سرمایه در گردش
A18: سهم سرمایه در گردش تأمین‌شده از تسهیلات کوتاه‌مدت | B18: WC.wc_loan_share | C18: درصد | D18: 0.3
A19: نرخ ذخیره مطالبات مشکوک‌الوصول | B19: WC.bad_debt | C19: درصد | D19: 0.01
A20: ضریب کاهش ارزش موجودی (کهنگی) | B20: WC.inv_obs | C20: درصد | D20: 0.005

Sheet IN_FIN
A1: ۶. ساختار سرمایه، تأمین مالی و برنامه CAPEX | B1: لایه ورودی
A2: درصد بدهی و حقوق صاحبان سهام، نرخ‌های بهره، دوره بازپرداخت، کارمزدها و برنامه تزریق سرمایه.
A7: الف) برنامه سرمایه‌گذاری ثابت (CAPEX)
D8: مبلغ کل | E8: سهم ارزی | F8: عمر مفید | G8: دوره جایگزینی | H8: درصد جایگزینی | I8: ارزش اسقاط | J8: تزریق t=0 | K8: تزریق t=1 | L8: تزریق t=2
A9: زمین | B9: CAP-01 | C9: میلیون ریال | D9: 300000 | E9: 0 | F9: 0 | G9: 0 | H9: 0 | I9: 1 | J9: 1 | K9: 0 | L9: 0
A10: محوطه‌سازی و ساختمان | B10: CAP-02 | C10: میلیون ریال | D10: 1600000 | E10: 0.1 | F10: 30 | G10: 0 | H10: 0 | I10: 0.3 | J10: 0.75 | K10: 0.25 | L10: 0
A11: ماشین‌آلات وارداتی | B11: CAP-03 | C11: میلیون ریال | D11: 4800000 | E11: 0.9 | F11: 15 | G11: 0 | H11: 0.6 | I11: 0.1 | J11: 0.75 | K11: 0.25 | L11: 0
A12: ماشین‌آلات داخلی | B12: CAP-04 | C12: میلیون ریال | D12: 1900000 | E12: 0.25 | F12: 12 | G12: 12 | H12: 0.7 | I12: 0.1 | J12: 0.75 | K12: 0.25 | L12: 0
A13: تأسیسات و تجهیزات جانبی | B13: CAP-05 | C13: میلیون ریال | D13: 1200000 | E13: 0.4 | F13: 15 | G13: 0 | H13: 0.5 | I13: 0.1 | J13: 0.75 | K13: 0.25 | L13: 0
A14: تصفیه‌خانه و تجهیزات زیست‌محیطی | B14: CAP-06 | C14: میلیون ریال | D14: 1050000 | E14: 0.3 | F14: 12 | G14: 12 | H14: 0.7 | I14: 0.1 | J14: 0.75 | K14: 0.25 | L14: 0
A15: تجهیزات حمل‌ونقل داخلی | B15: CAP-07 | C15: میلیون ریال | D15: 700000 | E15: 0.2 | F15: 8 | G15: 8 | H15: 0.8 | I15: 0.15 | J15: 0.6 | K15: 0.4 | L15: 0
A16: آزمایشگاه و ابزار دقیق | B16: CAP-08 | C16: میلیون ریال | D16: 450000 | E16: 0.6 | F16: 10 | G16: 10 | H16: 0.6 | I16: 0.1 | J16: 0.5 | K16: 0.5 | L16: 0
A17: مهندسی، نصب و راه‌اندازی | B17: CAP-09 | C17: میلیون ریال | D17: 900000 | E17: 0.1 | F17: 15 | G17: 0 | H17: 0 | I17: 0 | J17: 0.6 | K17: 0.4 | L17: 0
A18: هزینه‌های پیش از بهره‌برداری | B18: CAP-10 | C18: میلیون ریال | D18: 420000 | E18: 0.05 | F18: 5 | G18: 5 | H18: 0.5 | I18: 0 | J18: 0.3 | K18: 0.5 | L18: 0.2
A19: ذخیره احتیاطی فیزیکی | B19: CAP-11 | C19: میلیون ریال | D19: 1200000 | E19: 0.4 | F19: 15 | G19: 0 | H19: 0 | I19: 0.1 | J19: 0.4 | K19: 0.4 | L19: 0.2
A21: توضیح: عمر مفید صفر = مستهلک نمی‌شود (زمین). دوره جایگزینی صفر = جایگزینی در افق مدل ندارد.
A23: ب) ساختار تأمین مالی
A24: سهم تسهیلات بلندمدت از CAPEX | B24: FIN.debt_share | C24: درصد | D24: 0.6
A25: نرخ سود تسهیلات بلندمدت | B25: FIN.kd | C25: درصد | D25: 0.22
A26: کارمزد تخصیص/تعهد یکجا | B26: FIN.fee_arr | C26: درصد | D26: 0.015
A27: کارمزد تعهد روی مانده استفاده‌نشده | B27: FIN.fee_com | C27: درصد | D27: 0.005
A28: شاخص سال شروع بازپرداخت (t) | B28: FIN.repay_start | C28: شاخص | D28: 2
A29: دوره بازپرداخت (سال) | B29: FIN.repay_years | C29: سال | D29: 8
A30: روش بازپرداخت (1=اقساط مساوی اصل / 2=آنویتی) | B30: FIN.repay_method | C30: 1/2 | D30: 1
A31: نرخ سود تسهیلات کوتاه‌مدت (سرمایه در گردش) | B31: FIN.kd_st | C31: درصد | D31: 0.24
A32: حداقل DSCR قراردادی | B32: FIN.min_dscr | C32: ضریب | D32: 1.3
A33: سیاست تقسیم سود (درصد از سود خالص) | B33: FIN.payout | C33: درصد | D33: 0.4
A34: نرخ سود سپرده/درآمد غیرعملیاتی نقد | B34: FIN.i_income | C34: درصد | D34: 0.1

Sheet IN_SCEN
A1: ۷. تعریف سناریوها و محورهای حساسیت | B1: لایه ورودی
A2: ضرایب تعدیل مفروضات کلیدی در سناریوهای پایه / خوش‌بینانه / بدبینانه و محورهای ماتریس حساسیت.
A7: الف) انتخاب سناریوی فعال
A8: سناریوی فعال (۱=پایه، ۲=خوش‌بینانه، ۳=بدبینانه) | B8: SCEN.active_in | C8: شاخص | D8: 1
A9: تغییر این سلول کل مدل را به‌صورت زنجیره‌ای به‌روزرسانی می‌کند (ورودی ← موتور ← خروجی).
A11: ب) جدول ضرایب سناریوها
D12: پایه | E12: خوش‌بینانه | F12: بدبینانه
A13: ضریب حجم تولید و فروش | B13: VOL | C13: ضریب | D13: 1 | E13: 1.08 | F13: 0.88
A14: ضریب قیمت فروش محصولات | B14: PRICE | C14: ضریب | D14: 1 | E14: 1.1 | F14: 0.9
A15: ضریب قیمت خرید باتری ضایعاتی | B15: RM | C15: ضریب | D15: 1 | E15: 0.95 | F15: 1.08
A16: ضریب سایر هزینه‌های متغیر | B16: VAR | C16: ضریب | D16: 1 | E16: 0.97 | F16: 1.1
A17: ضریب هزینه‌های ثابت | B17: FIX | C17: ضریب | D17: 1 | E17: 0.95 | F17: 1.12
A18: ضریب سرمایه‌گذاری ثابت | B18: CAPEX | C18: ضریب | D18: 1 | E18: 0.95 | F18: 1.15
A19: ضریب نرخ ارز | B19: FX | C19: ضریب | D19: 1 | E19: 1.05 | F19: 0.95
A20: تعدیل نرخ تنزیل | B20: WACC | C20: واحد درصد | D20: 0 | E20: -0.02 | F20: 0.03
A21: تعدیل نرخ سود تسهیلات | B21: KD | C21: واحد درصد | D21: 0 | E21: -0.01 | F21: 0.03
A23: ج) محورهای ماتریس حساسیت
A24: انحراف نرخ بهره/تنزیل | B24: SCEN.ax_rate | C24: درصد | D24: -0.03 | E24: -0.015 | F24: 0 | G24: 0.015 | H24: 0.03
A25: انحراف نرخ ارز | B25: SCEN.ax_fx | C25: درصد | D25: -0.2 | E25: -0.1 | F25: 0 | G25: 0.1 | H25: 0.2
A26: انحراف قیمت فروش | B26: SCEN.ax_price | C26: درصد | D26: -0.15 | E26: -0.075 | F26: 0 | G26: 0.075 | H26: 0.15
A28: د) شرح سناریوها
A29: پایه: مفروضاتِ مندرج در شیت‌های ورودی بدون تعدیل (تمام ضرایب برابر یک یا صفر).
A30: خوش‌بینانه: رشد حجم و قیمت، کنترل هزینه‌ها و دسترسی بهتر به تأمین مالی.
A31: بدبینانه: افت حجم و قیمت، افزایش هزینه‌ها، افزایش CAPEX و نرخ تأمین مالی.

Sheet ENG_SCEN
A1: موتور سناریو و حساسیت | B1: موتور محاسبات
A2: اعمال ضرایب سناریوی فعال روی مفروضات کلیدی، ساخت مسیرهای تعدیل‌شده و شاخص‌های قیمتی.
A7: دوره (t) | D7: ='IN_MACRO'!D$23 | E7: ='IN_MACRO'!E$23 | F7: ='IN_MACRO'!F$23 | G7: ='IN_MACRO'!G$23 | H7: ='IN_MACRO'!H$23 | I7: ='IN_MACRO'!I$23 | J7: ='IN_MACRO'!J$23 | K7: ='IN_MACRO'!K$23 | ... P7: ='IN_MACRO'!P$23
A8: سال تقویمی | D8: ='IN_MACRO'!D$24 | E8: ='IN_MACRO'!E$24 | F8: ='IN_MACRO'!F$24 | G8: ='IN_MACRO'!G$24 | H8: ='IN_MACRO'!H$24 | I8: ='IN_MACRO'!I$24 | J8: ='IN_MACRO'!J$24 | K8: ='IN_MACRO'!K$24 | ... P8: ='IN_MACRO'!P$24
A9: الف) سناریوی فعال و ضرایب تعدیل
A10: سناریوی فعال (۱=پایه / ۲=خوش‌بینانه / ۳=بدبینانه) | C10: شاخص | D10: ='IN_SCEN'!$D$8
A11: ضریب حجم تولید و فروش — مقدار فعال | B11: VOL | C11: ضریب | D11: ='IN_SCEN'!$D$13 | E11: ='IN_SCEN'!$E$13 | F11: ='IN_SCEN'!$F$13 | G11: =INDEX('IN_SCEN'!$D$13:$F$13,'ENG_SCEN'!$D$10)
A12: ضریب قیمت فروش محصولات — مقدار فعال | B12: PRICE | C12: ضریب | D12: ='IN_SCEN'!$D$14 | E12: ='IN_SCEN'!$E$14 | F12: ='IN_SCEN'!$F$14 | G12: =INDEX('IN_SCEN'!$D$14:$F$14,'ENG_SCEN'!$D$10)
A13: ضریب قیمت خرید باتری ضایعاتی — مقدار فعال | B13: RM | C13: ضریب | D13: ='IN_SCEN'!$D$15 | E13: ='IN_SCEN'!$E$15 | F13: ='IN_SCEN'!$F$15 | G13: =INDEX('IN_SCEN'!$D$15:$F$15,'ENG_SCEN'!$D$10)
A14: ضریب سایر هزینه‌های متغیر — مقدار فعال | B14: VAR | C14: ضریب | D14: ='IN_SCEN'!$D$16 | E14: ='IN_SCEN'!$E$16 | F14: ='IN_SCEN'!$F$16 | G14: =INDEX('IN_SCEN'!$D$16:$F$16,'ENG_SCEN'!$D$10)
A15: ضریب هزینه‌های ثابت — مقدار فعال | B15: FIX | C15: ضریب | D15: ='IN_SCEN'!$D$17 | E15: ='IN_SCEN'!$E$17 | F15: ='IN_SCEN'!$F$17 | G15: =INDEX('IN_SCEN'!$D$17:$F$17,'ENG_SCEN'!$D$10)
A16: ضریب سرمایه‌گذاری ثابت — مقدار فعال | B16: CAPEX | C16: ضریب | D16: ='IN_SCEN'!$D$18 | E16: ='IN_SCEN'!$E$18 | F16: ='IN_SCEN'!$F$18 | G16: =INDEX('IN_SCEN'!$D$18:$F$18,'ENG_SCEN'!$D$10)
A17: ضریب نرخ ارز — مقدار فعال | B17: FX | C17: ضریب | D17: ='IN_SCEN'!$D$19 | E17: ='IN_SCEN'!$E$19 | F17: ='IN_SCEN'!$F$19 | G17: =INDEX('IN_SCEN'!$D$19:$F$19,'ENG_SCEN'!$D$10)
A18: تعدیل نرخ تنزیل — مقدار فعال | B18: WACC | C18: واحد درصد | D18: ='IN_SCEN'!$D$20 | E18: ='IN_SCEN'!$E$20 | F18: ='IN_SCEN'!$F$20 | G18: =INDEX('IN_SCEN'!$D$20:$F$20,'ENG_SCEN'!$D$10)
A19: تعدیل نرخ سود تسهیلات — مقدار فعال | B19: KD | C19: واحد درصد | D19: ='IN_SCEN'!$D$21 | E19: ='IN_SCEN'!$E$21 | F19: ='IN_SCEN'!$F$21 | G19: =INDEX('IN_SCEN'!$D$21:$F$21,'ENG_SCEN'!$D$10)
A21: ب) مسیرهای تعدیل‌شدهٔ اقتصاد کلان
A22: شاخص تورم عمومی | B22: SCEN.infl | C22: ─ | D22: ='IN_MACRO'!$D$25 | E22: ='IN_MACRO'!$E$25 | F22: ='IN_MACRO'!$F$25 | G22: ='IN_MACRO'!$G$25 | H22: ='IN_MACRO'!$H$25 | I22: ='IN_MACRO'!$I$25 | J22: ='IN_MACRO'!$J$25 | K22: ='IN_MACRO'!$K$25 | L22: ='IN_MACRO'!$L$25 | M22: ='IN_MACRO'!$M$25 | N22: ='IN_MACRO'!$N$25 | O22: ='IN_MACRO'!$O$25 | P22: ='IN_MACRO'!$P$25
A23: شاخص رشد دستمزد | B23: SCEN.wage | C23: ─ | D23: ='IN_MACRO'!$D$26 | E23: ='IN_MACRO'!$E$26 | F23: ='IN_MACRO'!$F$26 | G23: ='IN_MACRO'!$G$26 | H23: ='IN_MACRO'!$H$26 | I23: ='IN_MACRO'!$I$26 | J23: ='IN_MACRO'!$J$26 | K23: ='IN_MACRO'!$K$26 | L23: ='IN_MACRO'!$L$26 | M23: ='IN_MACRO'!$M$26 | N23: ='IN_MACRO'!$N$26 | O23: ='IN_MACRO'!$O$26 | P23: ='IN_MACRO'!$P$26
A24: شاخص رشد قیمت انرژی | B24: SCEN.energy | C24: ─ | D24: ='IN_MACRO'!$D$27 | E24: ='IN_MACRO'!$E$27 | F24: ='IN_MACRO'!$F$27 | G24: ='IN_MACRO'!$G$27 | H24: ='IN_MACRO'!$H$27 | I24: ='IN_MACRO'!$I$27 | J24: ='IN_MACRO'!$J$27 | K24: ='IN_MACRO'!$K$27 | L24: ='IN_MACRO'!$L$27 | M24: ='IN_MACRO'!$M$27 | N24: ='IN_MACRO'!$N$27 | O24: ='IN_MACRO'!$O$27 | P24: ='IN_MACRO'!$P$27
A25: شاخص قیمت تولیدکننده | B25: SCEN.ppi | C25: ─ | D25: ='IN_MACRO'!$D$32 | E25: ='IN_MACRO'!$E$32 | F25: ='IN_MACRO'!$F$32 | G25: ='IN_MACRO'!$G$32 | H25: ='IN_MACRO'!$H$32 | I25: ='IN_MACRO'!$I$32 | J25: ='IN_MACRO'!$J$32 | K25: ='IN_MACRO'!$K$32 | L25: ='IN_MACRO'!$L$32 | M25: ='IN_MACRO'!$M$32 | N25: ='IN_MACRO'!$N$32 | O25: ='IN_MACRO'!$O$32 | P25: ='IN_MACRO'!$P$32
A26: نرخ سود بدون ریسک | B26: SCEN.rf | C26: ─ | D26: ='IN_MACRO'!$D$30 | E26: ='IN_MACRO'!$E$30 | F26: ='IN_MACRO'!$F$30 | G26: ='IN_MACRO'!$G$30 | H26: ='IN_MACRO'!$H$30 | I26: ='IN_MACRO'!$I$30 | J26: ='IN_MACRO'!$J$30 | K26: ='IN_MACRO'!$K$30 | L26: ='IN_MACRO'!$L$30 | M26: ='IN_MACRO'!$M$30 | N26: ='IN_MACRO'!$N$30 | O26: ='IN_MACRO'!$O$30 | P26: ='IN_MACRO'!$P$30
A27: رشد GDP بخش هدف | B27: SCEN.gdp | C27: ─ | D27: ='IN_MACRO'!$D$31 | E27: ='IN_MACRO'!$E$31 | F27: ='IN_MACRO'!$F$31 | G27: ='IN_MACRO'!$G$31 | H27: ='IN_MACRO'!$H$31 | I27: ='IN_MACRO'!$I$31 | J27: ='IN_MACRO'!$J$31 | K27: ='IN_MACRO'!$K$31 | L27: ='IN_MACRO'!$L$31 | M27: ='IN_MACRO'!$M$31 | N27: ='IN_MACRO'!$N$31 | O27: ='IN_MACRO'!$O$31 | P27: ='IN_MACRO'!$P$31
A28: قیمت جهانی سرب LME | B28: SCEN.lme | C28: ─ | D28: ='IN_MACRO'!$D$29 | E28: ='IN_MACRO'!$E$29 | F28: ='IN_MACRO'!$F$29 | G28: ='IN_MACRO'!$G$29 | H28: ='IN_MACRO'!$H$29 | I28: ='IN_MACRO'!$I$29 | J28: ='IN_MACRO'!$J$29 | K28: ='IN_MACRO'!$K$29 | L28: ='IN_MACRO'!$L$29 | M28: ='IN_MACRO'!$M$29 | N28: ='IN_MACRO'!$N$29 | O28: ='IN_MACRO'!$O$29 | P28: ='IN_MACRO'!$P$29
A29: نرخ ارز (تعدیل‌شده) | B29: SCEN.fx | C29: ─ | D29: ='IN_MACRO'!$D$28*'ENG_SCEN'!$G$17 | E29: ='IN_MACRO'!$E$28*'ENG_SCEN'!$G$17 | F29: ='IN_MACRO'!$F$28*'ENG_SCEN'!$G$17 | G29: ='IN_MACRO'!$G$28*'ENG_SCEN'!$G$17 | H29: ='IN_MACRO'!$H$28*'ENG_SCEN'!$G$17 | I29: ='IN_MACRO'!$I$28*'ENG_SCEN'!$G$17 | J29: ='IN_MACRO'!$J$28*'ENG_SCEN'!$G$17 | K29: ='IN_MACRO'!$K$28*'ENG_SCEN'!$G$17 | L29: ='IN_MACRO'!$L$28*'ENG_SCEN'!$G$17 | M29: ='IN_MACRO'!$M$28*'ENG_SCEN'!$G$17 | N29: ='IN_MACRO'!$N$28*'ENG_SCEN'!$G$17 | O29: ='IN_MACRO'!$O$28*'ENG_SCEN'!$G$17 | P29: ='IN_MACRO'!$P$28*'ENG_SCEN'!$G$17
A31: ج) شاخص‌های قیمتی تجمعی (سال پایه = ۱)
A32: شاخص تورم عمومی | C32: ضریب | D32: =1 | E32: =D32*(1+'ENG_SCEN'!$E$22) | F32: =E32*(1+'ENG_SCEN'!$F$22) | G32: =F32*(1+'ENG_SCEN'!$G$22) | H32: =G32*(1+'ENG_SCEN'!$H$22) | I32: =H32*(1+'ENG_SCEN'!$I$22) | J32: =I32*(1+'ENG_SCEN'!$J$22) | K32: =J32*(1+'ENG_SCEN'!$K$22) | L32: =K32*(1+'ENG_SCEN'!$L$22) | M32: =L32*(1+'ENG_SCEN'!$M$22) | N32: =M32*(1+'ENG_SCEN'!$N$22) | O32: =N32*(1+'ENG_SCEN'!$O$22) | P32: =O32*(1+'ENG_SCEN'!$P$22)
A33: شاخص دستمزد | C33: ضریب | D33: =1 | E33: =D33*(1+'ENG_SCEN'!$E$23) | F33: =E33*(1+'ENG_SCEN'!$F$23) | G33: =F33*(1+'ENG_SCEN'!$G$23) | H33: =G33*(1+'ENG_SCEN'!$H$23) | I33: =H33*(1+'ENG_SCEN'!$I$23) | J33: =I33*(1+'ENG_SCEN'!$J$23) | K33: =J33*(1+'ENG_SCEN'!$K$23) | L33: =K33*(1+'ENG_SCEN'!$L$23) | M33: =L33*(1+'ENG_SCEN'!$M$23) | N33: =M33*(1+'ENG_SCEN'!$N$23) | O33: =N33*(1+'ENG_SCEN'!$O$23) | P33: =O33*(1+'ENG_SCEN'!$P$23)
A34: شاخص قیمت انرژی | C34: ضریب | D34: =1 | E34: =D34*(1+'ENG_SCEN'!$E$24) | F34: =E34*(1+'ENG_SCEN'!$F$24) | G34: =F34*(1+'ENG_SCEN'!$G$24) | H34: =G34*(1+'ENG_SCEN'!$H$24) | I34: =H34*(1+'ENG_SCEN'!$I$24) | J34: =I34*(1+'ENG_SCEN'!$J$24) | K34: =J34*(1+'ENG_SCEN'!$K$24) | L34: =K34*(1+'ENG_SCEN'!$L$24) | M34: =L34*(1+'ENG_SCEN'!$M$24) | N34: =M34*(1+'ENG_SCEN'!$N$24) | O34: =N34*(1+'ENG_SCEN'!$O$24) | P34: =O34*(1+'ENG_SCEN'!$P$24)
A35: شاخص قیمت تولیدکننده | C35: ضریب | D35: =1 | E35: =D35*(1+'ENG_SCEN'!$E$25) | F35: =E35*(1+'ENG_SCEN'!$F$25) | G35: =F35*(1+'ENG_SCEN'!$G$25) | H35: =G35*(1+'ENG_SCEN'!$H$25) | I35: =H35*(1+'ENG_SCEN'!$I$25) | J35: =I35*(1+'ENG_SCEN'!$J$25) | K35: =J35*(1+'ENG_SCEN'!$K$25) | L35: =K35*(1+'ENG_SCEN'!$L$25) | M35: =L35*(1+'ENG_SCEN'!$M$25) | N35: =M35*(1+'ENG_SCEN'!$N$25) | O35: =N35*(1+'ENG_SCEN'!$O$25) | P35: =O35*(1+'ENG_SCEN'!$P$25)
A36: شاخص نرخ ارز | D36: ='ENG_SCEN'!$D$29/'ENG_SCEN'!$D$29 | E36: ='ENG_SCEN'!$E$29/'ENG_SCEN'!$D$29 | F36: ='ENG_SCEN'!$F$29/'ENG_SCEN'!$D$29 | G36: ='ENG_SCEN'!$G$29/'ENG_SCEN'!$D$29 | H36: ='ENG_SCEN'!$H$29/'ENG_SCEN'!$D$29 | I36: ='ENG_SCEN'!$I$29/'ENG_SCEN'!$D$29 | J36: ='ENG_SCEN'!$J$29/'ENG_SCEN'!$D$29 | K36: ='ENG_SCEN'!$K$29/'ENG_SCEN'!$D$29 | L36: ='ENG_SCEN'!$L$29/'ENG_SCEN'!$D$29 | M36: ='ENG_SCEN'!$M$29/'ENG_SCEN'!$D$29 | N36: ='ENG_SCEN'!$N$29/'ENG_SCEN'!$D$29 | O36: ='ENG_SCEN'!$O$29/'ENG_SCEN'!$D$29 | P36: ='ENG_SCEN'!$P$29/'ENG_SCEN'!$D$29
A37: شاخص ترکیبی LME×ارز | D37: =('ENG_SCEN'!$D$28*'ENG_SCEN'!$D$29)/('ENG_SCEN'!$D$28*'ENG_SCEN'!$D$29) | E37: =('ENG_SCEN'!$E$28*'ENG_SCEN'!$E$29)/('ENG_SCEN'!$D$28*'ENG_SCEN'!$D$29) | F37: =('ENG_SCEN'!$F$28*'ENG_SCEN'!$F$29)/('ENG_SCEN'!$D$28*'ENG_SCEN'!$D$29) | G37: =('ENG_SCEN'!$G$28*'ENG_SCEN'!$G$29)/('ENG_SCEN'!$D$28*'ENG_SCEN'!$D$29) | H37: =('ENG_SCEN'!$H$28*'ENG_SCEN'!$H$29)/('ENG_SCEN'!$D$28*'ENG_SCEN'!$D$29) | I37: =('ENG_SCEN'!$I$28*'ENG_SCEN'!$I$29)/('ENG_SCEN'!$D$28*'ENG_SCEN'!$D$29) | J37: =('ENG_SCEN'!$J$28*'ENG_SCEN'!$J$29)/('ENG_SCEN'!$D$28*'ENG_SCEN'!$D$29) | K37: =('ENG_SCEN'!$K$28*'ENG_SCEN'!$K$29)/('ENG_SCEN'!$D$28*'ENG_SCEN'!$D$29) | L37: =('ENG_SCEN'!$L$28*'ENG_SCEN'!$L$29)/('ENG_SCEN'!$D$28*'ENG_SCEN'!$D$29) | M37: =('ENG_SCEN'!$M$28*'ENG_SCEN'!$M$29)/('ENG_SCEN'!$D$28*'ENG_SCEN'!$D$29) | N37: =('ENG_SCEN'!$N$28*'ENG_SCEN'!$N$29)/('ENG_SCEN'!$D$28*'ENG_SCEN'!$D$29) | O37: =('ENG_SCEN'!$O$28*'ENG_SCEN'!$O$29)/('ENG_SCEN'!$D$28*'ENG_SCEN'!$D$29) | P37: =('ENG_SCEN'!$P$28*'ENG_SCEN'!$P$29)/('ENG_SCEN'!$D$28*'ENG_SCEN'!$D$29)
A39: د) مدل سایهٔ سه سناریو (پایه / خوش‌بینانه / بدبینانه)
A40: توضیح: مدل تفصیلی برای «سناریوی فعال» اجرا می‌شود؛ این مدل سایه با استفاده از نسبت‌های ساختاریِ استخراج‌شده از همان مدل تفصیلی (فرمول‌محور، بدون عدد ثابت) شاخص‌های هر سه سناریو را هم‌زمان محاسبه می‌کند.
A41: سناریوی 1: پایه
A42: [1] حجم فروش محصولات (تن) | B42: SB1.vol | C42: تن | D42: ='ENG_OPS'!$D$82*'IN_SCEN'!$D$13 | E42: ='ENG_OPS'!$E$82*'IN_SCEN'!$D$13 | F42: ='ENG_OPS'!$F$82*'IN_SCEN'!$D$13 | G42: ='ENG_OPS'!$G$82*'IN_SCEN'!$D$13 | H42: ='ENG_OPS'!$H$82*'IN_SCEN'!$D$13 | I42: ='ENG_OPS'!$I$82*'IN_SCEN'!$D$13 | J42: ='ENG_OPS'!$J$82*'IN_SCEN'!$D$13 | K42: ='ENG_OPS'!$K$82*'IN_SCEN'!$D$13 | L42: ='ENG_OPS'!$L$82*'IN_SCEN'!$D$13 | M42: ='ENG_OPS'!$M$82*'IN_SCEN'!$D$13 | N42: ='ENG_OPS'!$N$82*'IN_SCEN'!$D$13 | O42: ='ENG_OPS'!$O$82*'IN_SCEN'!$D$13 | P42: ='ENG_OPS'!$P$82*'IN_SCEN'!$D$13
A43: [1] درآمد خالص هر تن | B43: SB1.price | C43: میلیون ریال/تن | D43: ='ENG_OPS'!$D$83*'IN_SCEN'!$D$14 | E43: ='ENG_OPS'!$E$83*'IN_SCEN'!$D$14 | F43: ='ENG_OPS'!$F$83*'IN_SCEN'!$D$14 | G43: ='ENG_OPS'!$G$83*'IN_SCEN'!$D$14 | H43: ='ENG_OPS'!$H$83*'IN_SCEN'!$D$14 | I43: ='ENG_OPS'!$I$83*'IN_SCEN'!$D$14 | J43: ='ENG_OPS'!$J$83*'IN_SCEN'!$D$14 | K43: ='ENG_OPS'!$K$83*'IN_SCEN'!$D$14 | L43: ='ENG_OPS'!$L$83*'IN_SCEN'!$D$14 | M43: ='ENG_OPS'!$M$83*'IN_SCEN'!$D$14 | N43: ='ENG_OPS'!$N$83*'IN_SCEN'!$D$14 | O43: ='ENG_OPS'!$O$83*'IN_SCEN'!$D$14 | P43: ='ENG_OPS'!$P$83*'IN_SCEN'!$D$14
A44: [1] درآمد خالص | B44: SB1.rev | C44: میلیون ریال | D44: ='ENG_SCEN'!$D$42*'ENG_SCEN'!$D$43 | E44: ='ENG_SCEN'!$E$42*'ENG_SCEN'!$E$43 | F44: ='ENG_SCEN'!$F$42*'ENG_SCEN'!$F$43 | G44: ='ENG_SCEN'!$G$42*'ENG_SCEN'!$G$43 | H44: ='ENG_SCEN'!$H$42*'ENG_SCEN'!$H$43 | I44: ='ENG_SCEN'!$I$42*'ENG_SCEN'!$I$43 | J44: ='ENG_SCEN'!$J$42*'ENG_SCEN'!$J$43 | K44: ='ENG_SCEN'!$K$42*'ENG_SCEN'!$K$43 | L44: ='ENG_SCEN'!$L$42*'ENG_SCEN'!$L$43 | M44: ='ENG_SCEN'!$M$42*'ENG_SCEN'!$M$43 | N44: ='ENG_SCEN'!$N$42*'ENG_SCEN'!$N$43 | O44: ='ENG_SCEN'!$O$42*'ENG_SCEN'!$O$43 | P44: ='ENG_SCEN'!$P$42*'ENG_SCEN'!$P$43
A45: [1] هزینه مواد اولیه | B45: SB1.rm | C45: میلیون ریال | D45: =@@ENG_COST|EC.rm|0@@*'IN_SCEN'!$D$13*'IN_SCEN'!$D$15 | E45: =@@ENG_COST|EC.rm|1@@*'IN_SCEN'!$D$13*'IN_SCEN'!$D$15 | F45: =@@ENG_COST|EC.rm|2@@*'IN_SCEN'!$D$13*'IN_SCEN'!$D$15 | G45: =@@ENG_COST|EC.rm|3@@*'IN_SCEN'!$D$13*'IN_SCEN'!$D$15 | H45: =@@ENG_COST|EC.rm|4@@*'IN_SCEN'!$D$13*'IN_SCEN'!$D$15 | I45: =@@ENG_COST|EC.rm|5@@*'IN_SCEN'!$D$13*'IN_SCEN'!$D$15 | J45: =@@ENG_COST|EC.rm|6@@*'IN_SCEN'!$D$13*'IN_SCEN'!$D$15 | K45: =@@ENG_COST|EC.rm|7@@*'IN_SCEN'!$D$13*'IN_SCEN'!$D$15 | L45: =@@ENG_COST|EC.rm|8@@*'IN_SCEN'!$D$13*'IN_SCEN'!$D$15 | M45: =@@ENG_COST|EC.rm|9@@*'IN_SCEN'!$D$13*'IN_SCEN'!$D$15 | N45: =@@ENG_COST|EC.rm|10@@*'IN_SCEN'!$D$13*'IN_SCEN'!$D$15 | O45: =@@ENG_COST|EC.rm|11@@*'IN_SCEN'!$D$13*'IN_SCEN'!$D$15 | P45: =@@ENG_COST|EC.rm|12@@*'IN_SCEN'!$D$13*'IN_SCEN'!$D$15
A46: [1] سایر هزینه‌های متغیر | B46: SB1.var | C46: میلیون ریال | D46: =@@ENG_COST|EC.var_ex_rm|0@@*'IN_SCEN'!$D$13*'IN_SCEN'!$D$16 | E46: =@@ENG_COST|EC.var_ex_rm|1@@*'IN_SCEN'!$D$13*'IN_SCEN'!$D$16 | F46: =@@ENG_COST|EC.var_ex_rm|2@@*'IN_SCEN'!$D$13*'IN_SCEN'!$D$16 | G46: =@@ENG_COST|EC.var_ex_rm|3@@*'IN_SCEN'!$D$13*'IN_SCEN'!$D$16 | H46: =@@ENG_COST|EC.var_ex_rm|4@@*'IN_SCEN'!$D$13*'IN_SCEN'!$D$16 | I46: =@@ENG_COST|EC.var_ex_rm|5@@*'IN_SCEN'!$D$13*'IN_SCEN'!$D$16 | J46: =@@ENG_COST|EC.var_ex_rm|6@@*'IN_SCEN'!$D$13*'IN_SCEN'!$D$16 | K46: =@@ENG_COST|EC.var_ex_rm|7@@*'IN_SCEN'!$D$13*'IN_SCEN'!$D$16 | L46: =@@ENG_COST|EC.var_ex_rm|8@@*'IN_SCEN'!$D$13*'IN_SCEN'!$D$16 | M46: =@@ENG_COST|EC.var_ex_rm|9@@*'IN_SCEN'!$D$13*'IN_SCEN'!$D$16 | N46: =@@ENG_COST|EC.var_ex_rm|10@@*'IN_SCEN'!$D$13*'IN_SCEN'!$D$16 | O46: =@@ENG_COST|EC.var_ex_rm|11@@*'IN_SCEN'!$D$13*'IN_SCEN'!$D$16 | P46: =@@ENG_COST|EC.var_ex_rm|12@@*'IN_SCEN'!$D$13*'IN_SCEN'!$D$16
A47: [1] هزینه‌های ثابت نقدی | B47: SB1.fix | C47: میلیون ریال | D47: =@@ENG_COST|EC.fixed_cash|0@@*'IN_SCEN'!$D$17 | E47: =@@ENG_COST|EC.fixed_cash|1@@*'IN_SCEN'!$D$17 | F47: =@@ENG_COST|EC.fixed_cash|2@@*'IN_SCEN'!$D$17 | G47: =@@ENG_COST|EC.fixed_cash|3@@*'IN_SCEN'!$D$17 | H47: =@@ENG_COST|EC.fixed_cash|4@@*'IN_SCEN'!$D$17 | I47: =@@ENG_COST|EC.fixed_cash|5@@*'IN_SCEN'!$D$17 | J47: =@@ENG_COST|EC.fixed_cash|6@@*'IN_SCEN'!$D$17 | K47: =@@ENG_COST|EC.fixed_cash|7@@*'IN_SCEN'!$D$17 | L47: =@@ENG_COST|EC.fixed_cash|8@@*'IN_SCEN'!$D$17 | M47: =@@ENG_COST|EC.fixed_cash|9@@*'IN_SCEN'!$D$17 | N47: =@@ENG_COST|EC.fixed_cash|10@@*'IN_SCEN'!$D$17 | O47: =@@ENG_COST|EC.fixed_cash|11@@*'IN_SCEN'!$D$17 | P47: =@@ENG_COST|EC.fixed_cash|12@@*'IN_SCEN'!$D$17
...

Sheet ENG_OPS
A1: موتور محاسبات عملیاتی | B1: موتور محاسبات
A2: تبدیل ورودی‌های فنی ایستگاه‌ها به ظرفیت، جریان مواد، محصول قابل فروش و درآمد.
A7: دوره (t) | D7: ='IN_MACRO'!D$23 | E7: ='IN_MACRO'!E$23 | F7: ='IN_MACRO'!F$23 | G7: ='IN_MACRO'!G$23 | H7: ='IN_MACRO'!H$23 | I7: ='IN_MACRO'!I$23 | J7: ='IN_MACRO'!J$23 | K7: ='IN_MACRO'!K$23 | ... P7: ='IN_MACRO'!P$23
A8: سال تقویمی | D8: ='IN_MACRO'!D$24 | E8: ='IN_MACRO'!E$24 | F8: ='IN_MACRO'!F$24 | G8: ='IN_MACRO'!G$24 | H8: ='IN_MACRO'!H$24 | I8: ='IN_MACRO'!I$24 | J8: ='IN_MACRO'!J$24 | K8: ='IN_MACRO'!K$24 | ... P8: ='IN_MACRO'!P$24
A9: الف) ظرفیت و بارگذاری
A10: ضریب دستیابی به ظرفیت (Ramp) | B10: OPS.ramp | C10: درصد | D10: ='IN_TECH'!$D$59*'IN_MACRO'!$D$34 | E10: ='IN_TECH'!$E$59*'IN_MACRO'!$E$34 | F10: ='IN_TECH'!$F$59*'IN_MACRO'!$F$34 | G10: ='IN_TECH'!$G$59*'IN_MACRO'!$G$34 | H10: ='IN_TECH'!$H$59*'IN_MACRO'!$H$34 | I10: ='IN_TECH'!$I$59*'IN_MACRO'!$I$34 | J10: ='IN_TECH'!$J$59*'IN_MACRO'!$J$34 | K10: ='IN_TECH'!$K$59*'IN_MACRO'!$K$34 | L10: ='IN_TECH'!$L$59*'IN_MACRO'!$L$34 | M10: ='IN_TECH'!$M$59*'IN_MACRO'!$M$34 | N10: ='IN_TECH'!$N$59*'IN_MACRO'!$N$34 | O10: ='IN_TECH'!$O$59*'IN_MACRO'!$O$34 | P10: ='IN_TECH'!$P$59*'IN_MACRO'!$P$34
A11: نرخ دسترسی کل خط (کمینهٔ ایستگاه‌ها) | B11: OPS.avail | C11: درصد | D11: =MIN('IN_TECH'!$D$38,'IN_TECH'!$E$38,'IN_TECH'!$F$38,'IN_TECH'!$G$38,'IN_TECH'!$H$38,'IN_TECH'!$I$38) | E11: =MIN('IN_TECH'!$D$38,'IN_TECH'!$E$38,'IN_TECH'!$F$38,'IN_TECH'!$G$38,'IN_TECH'!$H$38,'IN_TECH'!$I$38) | F11: =MIN('IN_TECH'!$D$38,'IN_TECH'!$E$38,'IN_TECH'!$F$38,'IN_TECH'!$G$38,'IN_TECH'!$H$38,'IN_TECH'!$I$38) | G11: =MIN('IN_TECH'!$D$38,'IN_TECH'!$E$38,'IN_TECH'!$F$38,'IN_TECH'!$G$38,'IN_TECH'!$H$38,'IN_TECH'!$I$38) | H11: =MIN('IN_TECH'!$D$38,'IN_TECH'!$E$38,'IN_TECH'!$F$38,'IN_TECH'!$G$38,'IN_TECH'!$H$38,'IN_TECH'!$I$38) | I11: =MIN('IN_TECH'!$D$38,'IN_TECH'!$E$38,'IN_TECH'!$F$38,'IN_TECH'!$G$38,'IN_TECH'!$H$38,'IN_TECH'!$I$38) | J11: =MIN('IN_TECH'!$D$38,'IN_TECH'!$E$38,'IN_TECH'!$F$38,'IN_TECH'!$G$38,'IN_TECH'!$H$38,'IN_TECH'!$I$38) | K11: =MIN('IN_TECH'!$D$38,'IN_TECH'!$E$38,'IN_TECH'!$F$38,'IN_TECH'!$G$38,'IN_TECH'!$H$38,'IN_TECH'!$I$38) | ... P11: =MIN('IN_TECH'!$D$38,'IN_TECH'!$E$38,'IN_TECH'!$F$38,'IN_TECH'!$G$38,'IN_TECH'!$H$38,'IN_TECH'!$I$38)
A12: ضریب بهره‌برداری مؤثر | B12: OPS.util | C12: درصد | D12: ='ENG_OPS'!$D$10*'ENG_OPS'!$D$11*'ENG_SCEN'!$G$11 | E12: ='ENG_OPS'!$E$10*'ENG_OPS'!$E$11*'ENG_SCEN'!$G$11 | F12: ='ENG_OPS'!$F$10*'ENG_OPS'!$F$11*'ENG_SCEN'!$G$11 | G12: ='ENG_OPS'!$G$10*'ENG_OPS'!$G$11*'ENG_SCEN'!$G$11 | H12: ='ENG_OPS'!$H$10*'ENG_OPS'!$H$11*'ENG_SCEN'!$G$11 | I12: ='ENG_OPS'!$I$10*'ENG_OPS'!$I$11*'ENG_SCEN'!$G$11 | J12: ='ENG_OPS'!$J$10*'ENG_OPS'!$J$11*'ENG_SCEN'!$G$11 | K12: ='ENG_OPS'!$K$10*'ENG_OPS'!$K$11*'ENG_SCEN'!$G$11 | L12: ='ENG_OPS'!$L$10*'ENG_OPS'!$L$11*'ENG_SCEN'!$G$11 | M12: ='ENG_OPS'!$M$10*'ENG_OPS'!$M$11*'ENG_SCEN'!$G$11 | N12: ='ENG_OPS'!$N$10*'ENG_OPS'!$N$11*'ENG_SCEN'!$G$11 | O12: ='ENG_OPS'!$O$10*'ENG_OPS'!$O$11*'ENG_SCEN'!$G$11 | P12: ='ENG_OPS'!$P$10*'ENG_OPS'!$P$11*'ENG_SCEN'!$G$11
A13: سهم خوراک ایستگاه 1 (به‌ازای هر تن ورودی) | B13: OPS.split.0 | C13: تن/تن | D13: =1 | E13: =1 | F13: =1 | G13: =1 | H13: =1 | I13: =1 | J13: =1 | K13: =1 | ... P13: =1
A14: سهم خوراک ایستگاه 2 (به‌ازای هر تن ورودی) | B14: OPS.split.1 | C14: تن/تن | D14: =(1-'IN_TECH'!$D$40) | E14: =(1-'IN_TECH'!$D$40) | F14: =(1-'IN_TECH'!$D$40) | G14: =(1-'IN_TECH'!$D$40) | H14: =(1-'IN_TECH'!$D$40) | I14: =(1-'IN_TECH'!$D$40) | J14: =(1-'IN_TECH'!$D$40) | K14: =(1-'IN_TECH'!$D$40) | ... P14: =(1-'IN_TECH'!$D$40)
A15: سهم خوراک ایستگاه 3 (به‌ازای هر تن ورودی) | B15: OPS.split.2 | C15: تن/تن | D15: =(((1-'IN_TECH'!$D$40)*(1-'IN_TECH'!$E$40))*'IN_TECH'!$D$27) | E15: =(((1-'IN_TECH'!$D$40)*(1-'IN_TECH'!$E$40))*'IN_TECH'!$D$27) | F15: =(((1-'IN_TECH'!$D$40)*(1-'IN_TECH'!$E$40))*'IN_TECH'!$D$27) | G15: =(((1-'IN_TECH'!$D$40)*(1-'IN_TECH'!$E$40))*'IN_TECH'!$D$27) | H15: =(((1-'IN_TECH'!$D$40)*(1-'IN_TECH'!$E$40))*'IN_TECH'!$D$27) | I15: =(((1-'IN_TECH'!$D$40)*(1-'IN_TECH'!$E$40))*'IN_TECH'!$D$27) | J15: =(((1-'IN_TECH'!$D$40)*(1-'IN_TECH'!$E$40))*'IN_TECH'!$D$27) | K15: =(((1-'IN_TECH'!$D$40)*(1-'IN_TECH'!$E$40))*'IN_TECH'!$D$27) | ... P15: =(((1-'IN_TECH'!$D$40)*(1-'IN_TECH'!$E$40))*'IN_TECH'!$D$27)
A16: سهم خوراک ایستگاه 4 (به‌ازای هر تن ورودی) | B16: OPS.split.3 | C16: تن/تن | D16: =(((((1-'IN_TECH'!$D$40)*(1-'IN_TECH'!$E$40))*'IN_TECH'!$D$27)*'IN_TECH'!$D$18*(1-'IN_TECH'!$F$40))+(((1-'IN_TECH'!$D$40)*(1-'IN_TECH'!$E$40))*'IN_TECH'!$D$28)) | E16: =(((((1-'IN_TECH'!$D$40)*(1-'IN_TECH'!$E$40))*'IN_TECH'!$D$27)*'IN_TECH'!$D$18*(1-'IN_TECH'!$F$40))+(((1-'IN_TECH'!$D$40)*(1-'IN_TECH'!$E$40))*'IN_TECH'!$D$28)) | F16: =(((((1-'IN_TECH'!$D$40)*(1-'IN_TECH'!$E$40))*'IN_TECH'!$D$27)*'IN_TECH'!$D$18*(1-'IN_TECH'!$F$40))+(((1-'IN_TECH'!$D$40)*(1-'IN_TECH'!$E$40))*'IN_TECH'!$D$28)) | G16: =(((((1-'IN_TECH'!$D$40)*(1-'IN_TECH'!$E$40))*'IN_TECH'!$D$27)*'IN_TECH'!$D$18*(1-'IN_TECH'!$F$40))+(((1-'IN_TECH'!$D$40)*(1-'IN_TECH'!$E$40))*'IN_TECH'!$D$28)) | H16: =(((((1-'IN_TECH'!$D$40)*(1-'IN_TECH'!$E$40))*'IN_TECH'!$D$27)*'IN_TECH'!$D$18*(1-'IN_TECH'!$F$40))+(((1-'IN_TECH'!$D$40)*(1-'IN_TECH'!$E$40))*'IN_TECH'!$D$28)) | I16: =(((((1-'IN_TECH'!$D$40)*(1-'IN_TECH'!$E$40))*'IN_TECH'!$D$27)*'IN_TECH'!$D$18*(1-'IN_TECH'!$F$40))+(((1-'IN_TECH'!$D$40)*(1-'IN_TECH'!$E$40))*'IN_TECH'!$D$28)) | J16: =(((((1-'IN_TECH'!$D$40)*(1-'IN_TECH'!$E$40))*'IN_TECH'!$D$27)*'IN_TECH'!$D$18*(1-'IN_TECH'!$F$40))+(((1-'IN_TECH'!$D$40)*(1-'IN_TECH'!$E$40))*'IN_TECH'!$D$28)) | K16: =(((((1-'IN_TECH'!$D$40)*(1-'IN_TECH'!$E$40))*'IN_TECH'!$D$27)*'IN_TECH'!$D$18*(1-'IN_TECH'!$F$40))+(((1-'IN_TECH'!$D$40)*(1-'IN_TECH'!$E$40))*'IN_TECH'!$D$28)) | ... P16: =(((((1-'IN_TECH'!$D$40)*(1-'IN_TECH'!$E$40))*'IN_TECH'!$D$27)*'IN_TECH'!$D$18*(1-'IN_TECH'!$F$40))+(((1-'IN_TECH'!$D$40)*(1-'IN_TECH'!$E$40))*'IN_TECH'!$D$28))
A17: سهم خوراک ایستگاه 5 (به‌ازای هر تن ورودی) | B17: OPS.split.4 | C17: تن/تن | D17: =((((((1-'IN_TECH'!$D$40)*(1-'IN_TECH'!$E$40))*'IN_TECH'!$D$27)*'IN_TECH'!$D$18*(1-'IN_TECH'!$F$40))*'IN_TECH'!$D$16+(((1-'IN_TECH'!$D$40)*(1-'IN_TECH'!$E$40))*'IN_TECH'!$D$28)*'IN_TECH'!$D$17)*'IN_TECH'!$D$19*(1-'IN_TECH'!$G$40)) | E17: =((((((1-'IN_TECH'!$D$40)*(1-'IN_TECH'!$E$40))*'IN_TECH'!$D$27)*'IN_TECH'!$D$18*(1-'IN_TECH'!$F$40))*'IN_TECH'!$D$16+(((1-'IN_TECH'!$D$40)*(1-'IN_TECH'!$E$40))*'IN_TECH'!$D$28)*'IN_TECH'!$D$17)*'IN_TECH'!$D$19*(1-'IN_TECH'!$G$40)) | F17: =((((((1-'IN_TECH'!$D$40)*(1-'IN_TECH'!$E$40))*'IN_TECH'!$D$27)*'IN_TECH'!$D$18*(1-'IN_TECH'!$F$40))*'IN_TECH'!$D$16+(((1-'IN_TECH'!$D$40)*(1-'IN_TECH'!$E$40))*'IN_TECH'!$D$28)*'IN_TECH'!$D$17)*'IN_TECH'!$D$19*(1-'IN_TECH'!$G$40)) | G17: =((((((1-'IN_TECH'!$D$40)*(1-'IN_TECH'!$E$40))*'IN_TECH'!$D$27)*'IN_TECH'!$D$18*(1-'IN_TECH'!$F$40))*'IN_TECH'!$D$16+(((1-'IN_TECH'!$D$40)*(1-'IN_TECH'!$E$40))*'IN_TECH'!$D$28)*'IN_TECH'!$D$17)*'IN_TECH'!$D$19*(1-'IN_TECH'!$G$40)) | H17: =((((((1-'IN_TECH'!$D$40)*(1-'IN_TECH'!$E$40))*'IN_TECH'!$D$27)*'IN_TECH'!$D$18*(1-'IN_TECH'!$F$40))*'IN_TECH'!$D$16+(((1-'IN_TECH'!$D$40)*(1-'IN_TECH'!$E$40))*'IN_TECH'!$D$28)*'IN_TECH'!$D$17)*'IN_TECH'!$D$19*(1-'IN_TECH'!$G$40)) | I17: =((((((1-'IN_TECH'!$D$40)*(1-'IN_TECH'!$E$40))*'IN_TECH'!$D$27)*'IN_TECH'!$D$18*(1-'IN_TECH'!$F$40))*'IN_TECH'!$D$16+(((1-'IN_TECH'!$D$40)*(1-'IN_TECH'!$E$40))*'IN_TECH'!$D$28)*'IN_TECH'!$D$17)*'IN_TECH'!$D$19*(1-'IN_TECH'!$G$40)) | J17: =((((((1-'IN_TECH'!$D$40)*(1-'IN_TECH'!$E$40))*'IN_TECH'!$D$27)*'IN_TECH'!$D$18*(1-'IN_TECH'!$F$40))*'IN_TECH'!$D$16+(((1-'IN_TECH'!$D$40)*(1-'IN_TECH'!$E$40))*'IN_TECH'!$D$28)*'IN_TECH'!$D$17)*'IN_TECH'!$D$19*(1-'IN_TECH'!$G$40)) | K17: =((((((1-'IN_TECH'!$D$40)*(1-'IN_TECH'!$E$40))*'IN_TECH'!$D$27)*'IN_TECH'!$D$18*(1-'IN_TECH'!$F$40))*'IN_TECH'!$D$16+(((1-'IN_TECH'!$D$40)*(1-'IN_TECH'!$E$40))*'IN_TECH'!$D$28)*'IN_TECH'!$D$17)*'IN_TECH'!$D$19*(1-'IN_TECH'!$G$40)) | ... P17: =((((((1-'IN_TECH'!$D$40)*(1-'IN_TECH'!$E$40))*'IN_TECH'!$D$27)*'IN_TECH'!$D$18*(1-'IN_TECH'!$F$40))*'IN_TECH'!$D$16+(((1-'IN_TECH'!$D$40)*(1-'IN_TECH'!$E$40))*'IN_TECH'!$D$28)*'IN_TECH'!$D$17)*'IN_TECH'!$D$19*(1-'IN_TECH'!$G$40))
A18: سهم خوراک ایستگاه 6 (به‌ازای هر تن ورودی) | B18: OPS.split.5 | C18: تن/تن | D18: =((((((((1-'IN_TECH'!$D$40)*(1-'IN_TECH'!$E$40))*'IN_TECH'!$D$27)*'IN_TECH'!$D$18*(1-'IN_TECH'!$F$40))*'IN_TECH'!$D$16+(((1-'IN_TECH'!$D$40)*(1-'IN_TECH'!$E$40))*'IN_TECH'!$D$28)*'IN_TECH'!$D$17)*'IN_TECH'!$D$19*(1-'IN_TECH'!$G$40))*'IN_TECH'!$D$20*(1-'IN_TECH'!$H$40))+(((1-'IN_TECH'!$D$40)*(1-'IN_TECH'!$E$40))*'IN_TECH'!$D$29)*'IN_TECH'!$D$21+'IN_TECH'!$D$22) | E18: =((((((((1-'IN_TECH'!$D$40)*(1-'IN_TECH'!$E$40))*'IN_TECH'!$D$27)*'IN_TECH'!$D$18*(1-'IN_TECH'!$F$40))*'IN_TECH'!$D$16+(((1-'IN_TECH'!$D$40)*(1-'IN_TECH'!$E$40))*'IN_TECH'!$D$28)*'IN_TECH'!$D$17)*'IN_TECH'!$D$19*(1-'IN_TECH'!$G$40))*'IN_TECH'!$D$20*(1-'IN_TECH'!$H$40))+(((1-'IN_TECH'!$D$40)*(1-'IN_TECH'!$E$40))*'IN_TECH'!$D$29)*'IN_TECH'!$D$21+'IN_TECH'!$D$22) | F18: =((((((((1-'IN_TECH'!$D$40)*(1-'IN_TECH'!$E$40))*'IN_TECH'!$D$27)*'IN_TECH'!$D$18*(1-'IN_TECH'!$F$40))*'IN_TECH'!$D$16+(((1-'IN_TECH'!$D$40)*(1-'IN_TECH'!$E$40))*'IN_TECH'!$D$28)*'IN_TECH'!$D$17)*'IN_TECH'!$D$19*(1-'IN_TECH'!$G$40))*'IN_TECH'!$D$20*(1-'IN_TECH'!$H$40))+(((1-'IN_TECH'!$D$40)*(1-'IN_TECH'!$E$40))*'IN_TECH'!$D$29)*'IN_TECH'!$D$21+'IN_TECH'!$D$22) | G18: =((((((((1-'IN_TECH'!$D$40)*(1-'IN_TECH'!$E$40))*'IN_TECH'!$D$27)*'IN_TECH'!$D$18*(1-'IN_TECH'!$F$40))*'IN_TECH'!$D$16+(((1-'IN_TECH'!$D$40)*(1-'IN_TECH'!$E$40))*'IN_TECH'!$D$28)*'IN_TECH'!$D$17)*'IN_TECH'!$D$19*(1-'IN_TECH'!$G$40))*'IN_TECH'!$D$20*(1-'IN_TECH'!$H$40))+(((1-'IN_TECH'!$D$40)*(1-'IN_TECH'!$E$40))*'IN_TECH'!$D$29)*'IN_TECH'!$D$21+'IN_TECH'!$D$22) | H18: =((((((((1-'IN_TECH'!$D$40)*(1-'IN_TECH'!$E$40))*'IN_TECH'!$D$27)*'IN_TECH'!$D$18*(1-'IN_TECH'!$F$40))*'IN_TECH'!$D$16+(((1-'IN_TECH'!$D$40)*(1-'IN_TECH'!$E$40))*'IN_TECH'!$D$28)*'IN_TECH'!$D$17)*'IN_TECH'!$D$19*(1-'IN_TECH'!$G$40))*'IN_TECH'!$D$20*(1-'IN_TECH'!$H$40))+(((1-'IN_TECH'!$D$40)*(1-'IN_TECH'!$E$40))*'IN_TECH'!$D$29)*'IN_TECH'!$D$21+'IN_TECH'!$D$22) | I18: =((((((((1-'IN_TECH'!$D$40)*(1-'IN_TECH'!$E$40))*'IN_TECH'!$D$27)*'IN_TECH'!$D$18*(1-'IN_TECH'!$F$40))*'IN_TECH'!$D$16+(((1-'IN_TECH'!$D$40)*(1-'IN_TECH'!$E$40))*'IN_TECH'!$D$28)*'IN_TECH'!$D$17)*'IN_TECH'!$D$19*(1-'IN_TECH'!$G$40))*'IN_TECH'!$D$20*(1-'IN_TECH'!$H$40))+(((1-'IN_TECH'!$D$40)*(1-'IN_TECH'!$E$40))*'IN_TECH'!$D$29)*'IN_TECH'!$D$21+'IN_TECH'!$D$22) | J18: =((((((((1-'IN_TECH'!$D$40)*(1-'IN_TECH'!$E$40))*'IN_TECH'!$D$27)*'IN_TECH'!$D$18*(1-'IN_TECH'!$F$40))*'IN_TECH'!$D$16+(((1-'IN_TECH'!$D$40)*(1-'IN_TECH'!$E$40))*'IN_TECH'!$D$28)*'IN_TECH'!$D$17)*'IN_TECH'!$D$19*(1-'IN_TECH'!$G$40))*'IN_TECH'!$D$20*(1-'IN_TECH'!$H$40))+(((1-'IN_TECH'!$D$40)*(1-'IN_TECH'!$E$40))*'IN_TECH'!$D$29)*'IN_TECH'!$D$21+'IN_TECH'!$D$22) | K18: =((((((((1-'IN_TECH'!$D$40)*(1-'IN_TECH'!$E$40))*'IN_TECH'!$D$27)*'IN_TECH'!$D$18*(1-'IN_TECH'!$F$40))*'IN_TECH'!$D$16+(((1-'IN_TECH'!$D$40)*(1-'IN_TECH'!$E$40))*'IN_TECH'!$D$28)*'IN_TECH'!$D$17)*'IN_TECH'!$D$19*(1-'IN_TECH'!$G$40))*'IN_TECH'!$D$20*(1-'IN_TECH'!$H$40))+(((1-'IN_TECH'!$D$40)*(1-'IN_TECH'!$E$40))*'IN_TECH'!$D$29)*'IN_TECH'!$D$21+'IN_TECH'!$D$22) | ... P18: =((((((((1-'IN_TECH'!$D$40)*(1-'IN_TECH'!$E$40))*'IN_TECH'!$D$27)*'IN_TECH'!$D$18*(1-'IN_TECH'!$F$40))*'IN_TECH'!$D$16+(((1-'IN_TECH'!$D$40)*(1-'IN_TECH'!$E$40))*'IN_TECH'!$D$28)*'IN_TECH'!$D$17)*'IN_TECH'!$D$19*(1-'IN_TECH'!$G$40))*'IN_TECH'!$D$20*(1-'IN_TECH'!$H$40))+(((1-'IN_TECH'!$D$40)*(1-'IN_TECH'!$E$40))*'IN_TECH'!$D$29)*'IN_TECH'!$D$21+'IN_TECH'!$D$22)
A19: بیشینهٔ ورودی قابل پردازش (محدودیت گلوگاه) | B19: OPS.intake_cap | C19: تن | D19: =MIN(IFERROR('IN_TECH'!$D$36/'ENG_OPS'!$D$13,1E+15),IFERROR('IN_TECH'!$E$36/'ENG_OPS'!$D$14,1E+15),IFERROR('IN_TECH'!$F$36/'ENG_OPS'!$D$15,1E+15),IFERROR('IN_TECH'!$G$36/'ENG_OPS'!$D$16,1E+15),IFERROR('IN_TECH'!$H$36/'ENG_OPS'!$D$17,1E+15),IFERROR('IN_TECH'!$I$36/'ENG_OPS'!$D$18,1E+15)) | E19: =MIN(IFERROR('IN_TECH'!$D$36/'ENG_OPS'!$E$13,1E+15),IFERROR('IN_TECH'!$E$36/'ENG_OPS'!$E$14,1E+15),IFERROR('IN_TECH'!$F$36/'ENG_OPS'!$E$15,1E+15),IFERROR('IN_TECH'!$G$36/'ENG_OPS'!$E$16,1E+15),IFERROR('IN_TECH'!$H$36/'ENG_OPS'!$E$17,1E+15),IFERROR('IN_TECH'!$I$36/'ENG_OPS'!$E$18,1E+15)) | F19: =MIN(IFERROR('IN_TECH'!$D$36/'ENG_OPS'!$F$13,1E+15),IFERROR('IN_TECH'!$E$36/'ENG_OPS'!$F$14,1E+15),IFERROR('IN_TECH'!$F$36/'ENG_OPS'!$F$15,1E+15),IFERROR('IN_TECH'!$G$36/'ENG_OPS'!$F$16,1E+15),IFERROR('IN_TECH'!$H$36/'ENG_OPS'!$F$17,1E+15),IFERROR('IN_TECH'!$I$36/'ENG_OPS'!$F$18,1E+15)) | G19: =MIN(IFERROR('IN_TECH'!$D$36/'ENG_OPS'!$G$13,1E+15),IFERROR('IN_TECH'!$E$36/'ENG_OPS'!$G$14,1E+15),IFERROR('IN_TECH'!$F$36/'ENG_OPS'!$G$15,1E+15),IFERROR('IN_TECH'!$G$36/'ENG_OPS'!$G$16,1E+15),IFERROR('IN_TECH'!$H$36/'ENG_OPS'!$G$17,1E+15),IFERROR('IN_TECH'!$I$36/'ENG_OPS'!$G$18,1E+15)) | H19: =MIN(IFERROR('IN_TECH'!$D$36/'ENG_OPS'!$H$13,1E+15),IFERROR('IN_TECH'!$E$36/'ENG_OPS'!$H$14,1E+15),IFERROR('IN_TECH'!$F$36/'ENG_OPS'!$H$15,1E+15),IFERROR('IN_TECH'!$G$36/'ENG_OPS'!$H$16,1E+15),IFERROR('IN_TECH'!$H$36/'ENG_OPS'!$H$17,1E+15),IFERROR('IN_TECH'!$I$36/'ENG_OPS'!$H$18,1E+15)) | I19: =MIN(IFERROR('IN_TECH'!$D$36/'ENG_OPS'!$I$13,1E+15),IFERROR('IN_TECH'!$E$36/'ENG_OPS'!$I$14,1E+15),IFERROR('IN_TECH'!$F$36/'ENG_OPS'!$I$15,1E+15),IFERROR('IN_TECH'!$G$36/'ENG_OPS'!$I$16,1E+15),IFERROR('IN_TECH'!$H$36/'ENG_OPS'!$I$17,1E+15),IFERROR('IN_TECH'!$I$36/'ENG_OPS'!$I$18,1E+15)) | J19: =MIN(IFERROR('IN_TECH'!$D$36/'ENG_OPS'!$J$13,1E+15),IFERROR('IN_TECH'!$E$36/'ENG_OPS'!$J$14,1E+15),IFERROR('IN_TECH'!$F$36/'ENG_OPS'!$J$15,1E+15),IFERROR('IN_TECH'!$G$36/'ENG_OPS'!$J$16,1E+15),IFERROR('IN_TECH'!$H$36/'ENG_OPS'!$J$17,1E+15),IFERROR('IN_TECH'!$I$36/'ENG_OPS'!$J$18,1E+15)) | K19: =MIN(IFERROR('IN_TECH'!$D$36/'ENG_OPS'!$K$13,1E+15),IFERROR('IN_TECH'!$E$36/'ENG_OPS'!$K$14,1E+15),IFERROR('IN_TECH'!$F$36/'ENG_OPS'!$K$15,1E+15),IFERROR('IN_TECH'!$G$36/'ENG_OPS'!$K$16,1E+15),IFERROR('IN_TECH'!$H$36/'ENG_OPS'!$K$17,1E+15),IFERROR('IN_TECH'!$I$36/'ENG_OPS'!$K$18,1E+15)) | L19: =MIN(IFERROR('IN_TECH'!$D$36/'ENG_OPS'!$L$13,1E+15),IFERROR('IN_TECH'!$E$36/'ENG_OPS'!$L$14,1E+15),IFERROR('IN_TECH'!$F$36/'ENG_OPS'!$L$15,1E+15),IFERROR('IN_TECH'!$G$36/'ENG_OPS'!$L$16,1E+15),IFERROR('IN_TECH'!$H$36/'ENG_OPS'!$L$17,1E+15),IFERROR('IN_TECH'!$I$36/'ENG_OPS'!$L$18,1E+15)) | M19: =MIN(IFERROR('IN_TECH'!$D$36/'ENG_OPS'!$M$13,1E+15),IFERROR('IN_TECH'!$E$36/'ENG_OPS'!$M$14,1E+15),IFERROR('IN_TECH'!$F$36/'ENG_OPS'!$M$15,1E+15),IFERROR('IN_TECH'!$G$36/'ENG_OPS'!$M$16,1E+15),IFERROR('IN_TECH'!$H$36/'ENG_OPS'!$M$17,1E+15),IFERROR('IN_TECH'!$I$36/'ENG_OPS'!$M$18,1E+15)) | N19: =MIN(IFERROR('IN_TECH'!$D$36/'ENG_OPS'!$N$13,1E+15),IFERROR('IN_TECH'!$E$36/'ENG_OPS'!$N$14,1E+15),IFERROR('IN_TECH'!$F$36/'ENG_OPS'!$N$15,1E+15),IFERROR('IN_TECH'!$G$36/'ENG_OPS'!$N$16,1E+15),IFERROR('IN_TECH'!$H$36/'ENG_OPS'!$N$17,1E+15),IFERROR('IN_TECH'!$I$36/'ENG_OPS'!$N$18,1E+15)) | O19: =MIN(IFERROR('IN_TECH'!$D$36/'ENG_OPS'!$O$13,1E+15),IFERROR('IN_TECH'!$E$36/'ENG_OPS'!$O$14,1E+15),IFERROR('IN_TECH'!$F$36/'ENG_OPS'!$O$15,1E+15),IFERROR('IN_TECH'!$G$36/'ENG_OPS'!$O$16,1E+15),IFERROR('IN_TECH'!$H$36/'ENG_OPS'!$O$17,1E+15),IFERROR('IN_TECH'!$I$36/'ENG_OPS'!$O$18,1E+15)) | P19: =MIN(IFERROR('IN_TECH'!$D$36/'ENG_OPS'!$P$13,1E+15),IFERROR('IN_TECH'!$E$36/'ENG_OPS'!$P$14,1E+15),IFERROR('IN_TECH'!$F$36/'ENG_OPS'!$P$15,1E+15),IFERROR('IN_TECH'!$G$36/'ENG_OPS'!$P$16,1E+15),IFERROR('IN_TECH'!$H$36/'ENG_OPS'!$P$17,1E+15),IFERROR('IN_TECH'!$I$36/'ENG_OPS'!$P$18,1E+15))
A20: ورودی واقعی باتری ضایعاتی | B20: OPS.intake | C20: تن | D20: =MIN('IN_TECH'!$D$8*'ENG_OPS'!$D$12,'ENG_OPS'!$D$19) | E20: =MIN('IN_TECH'!$D$8*'ENG_OPS'!$E$12,'ENG_OPS'!$E$19) | F20: =MIN('IN_TECH'!$D$8*'ENG_OPS'!$F$12,'ENG_OPS'!$F$19) | G20: =MIN('IN_TECH'!$D$8*'ENG_OPS'!$G$12,'ENG_OPS'!$G$19) | H20: =MIN('IN_TECH'!$D$8*'ENG_OPS'!$H$12,'ENG_OPS'!$H$19) | I20: =MIN('IN_TECH'!$D$8*'ENG_OPS'!$I$12,'ENG_OPS'!$I$19) | J20: =MIN('IN_TECH'!$D$8*'ENG_OPS'!$J$12,'ENG_OPS'!$J$19) | K20: =MIN('IN_TECH'!$D$8*'ENG_OPS'!$K$12,'ENG_OPS'!$K$19) | L20: =MIN('IN_TECH'!$D$8*'ENG_OPS'!$L$12,'ENG_OPS'!$L$19) | M20: =MIN('IN_TECH'!$D$8*'ENG_OPS'!$M$12,'ENG_OPS'!$M$19) | N20: =MIN('IN_TECH'!$D$8*'ENG_OPS'!$N$12,'ENG_OPS'!$N$19) | O20: =MIN('IN_TECH'!$D$8*'ENG_OPS'!$O$12,'ENG_OPS'!$O$19) | P20: =MIN('IN_TECH'!$D$8*'ENG_OPS'!$P$12,'ENG_OPS'!$P$19)
A21: ساعات اسمی کارکرد در سال | B21: OPS.hours_nom | C21: ساعت | D21: ='IN_TECH'!$D$9*'IN_TECH'!$D$10*'IN_TECH'!$D$11 | E21: ='IN_TECH'!$D$9*'IN_TECH'!$D$10*'IN_TECH'!$D$11 | F21: ='IN_TECH'!$D$9*'IN_TECH'!$D$10*'IN_TECH'!$D$11 | G21: ='IN_TECH'!$D$9*'IN_TECH'!$D$10*'IN_TECH'!$D$11 | H21: ='IN_TECH'!$D$9*'IN_TECH'!$D$10*'IN_TECH'!$D$11 | I21: ='IN_TECH'!$D$9*'IN_TECH'!$D$10*'IN_TECH'!$D$11 | J21: ='IN_TECH'!$D$9*'IN_TECH'!$D$10*'IN_TECH'!$D$11 | K21: ='IN_TECH'!$D$9*'IN_TECH'!$D$10*'IN_TECH'!$D$11 | ... P21: ='IN_TECH'!$D$9*'IN_TECH'!$D$10*'IN_TECH'!$D$11
A22: ساعات مؤثر کارکرد | B22: OPS.hours | C22: ساعت | D22: =MAX(0,('ENG_OPS'!$D$21-'IN_TECH'!$D$12-'IN_TECH'!$D$13))*'ENG_OPS'!$D$12 | E22: =MAX(0,('ENG_OPS'!$E$21-'IN_TECH'!$D$12-'IN_TECH'!$D$13))*'ENG_OPS'!$E$12 | F22: =MAX(0,('ENG_OPS'!$F$21-'IN_TECH'!$D$12-'IN_TECH'!$D$13))*'ENG_OPS'!$F$12 | G22: =MAX(0,('ENG_OPS'!$G$21-'IN_TECH'!$D$12-'IN_TECH'!$D$13))*'ENG_OPS'!$G$12 | H22: =MAX(0,('ENG_OPS'!$H$21-'IN_TECH'!$D$12-'IN_TECH'!$D$13))*'ENG_OPS'!$H$12 | I22: =MAX(0,('ENG_OPS'!$I$21-'IN_TECH'!$D$12-'IN_TECH'!$D$13))*'ENG_OPS'!$I$12 | J22: =MAX(0,('ENG_OPS'!$J$21-'IN_TECH'!$D$12-'IN_TECH'!$D$13))*'ENG_OPS'!$J$12 | K22: =MAX(0,('ENG_OPS'!$K$21-'IN_TECH'!$D$12-'IN_TECH'!$D$13))*'ENG_OPS'!$K$12 | L22: =MAX(0,('ENG_OPS'!$L$21-'IN_TECH'!$D$12-'IN_TECH'!$D$13))*'ENG_OPS'!$L$12 | M22: =MAX(0,('ENG_OPS'!$M$21-'IN_TECH'!$D$12-'IN_TECH'!$D$13))*'ENG_OPS'!$M$12 | N22: =MAX(0,('ENG_OPS'!$N$21-'IN_TECH'!$D$12-'IN_TECH'!$D$13))*'ENG_OPS'!$N$12 | O22: =MAX(0,('ENG_OPS'!$O$21-'IN_TECH'!$D$12-'IN_TECH'!$D$13))*'ENG_OPS'!$O$12 | P22: =MAX(0,('ENG_OPS'!$P$21-'IN_TECH'!$D$12-'IN_TECH'!$D$13))*'ENG_OPS'!$P$12
A23: نرخ استفاده از ظرفیت اسمی | B23: OPS.caputil | C23: درصد | D23: =IFERROR('ENG_OPS'!$D$20/'IN_TECH'!$D$8,0) | E23: =IFERROR('ENG_OPS'!$E$20/'IN_TECH'!$D$8,0) | F23: =IFERROR('ENG_OPS'!$F$20/'IN_TECH'!$D$8,0) | G23: =IFERROR('ENG_OPS'!$G$20/'IN_TECH'!$D$8,0) | H23: =IFERROR('ENG_OPS'!$H$20/'IN_TECH'!$D$8,0) | I23: =IFERROR('ENG_OPS'!$I$20/'IN_TECH'!$D$8,0) | J23: =IFERROR('ENG_OPS'!$J$20/'IN_TECH'!$D$8,0) | K23: =IFERROR('ENG_OPS'!$K$20/'IN_TECH'!$D$8,0) | L23: =IFERROR('ENG_OPS'!$L$20/'IN_TECH'!$D$8,0) | M23: =IFERROR('ENG_OPS'!$M$20/'IN_TECH'!$D$8,0) | N23: =IFERROR('ENG_OPS'!$N$20/'IN_TECH'!$D$8,0) | O23: =IFERROR('ENG_OPS'!$O$20/'IN_TECH'!$D$8,0) | P23: =IFERROR('ENG_OPS'!$P$20/'IN_TECH'!$D$8,0)
A25: ب) جریان مواد و تراز جرم
A26: خروجی ایستگاه ۱ (پس از تخلیه) | B26: OPS.s1out | C26: تن | D26: ='ENG_OPS'!$D$20*(1-'IN_TECH'!$D$40) | E26: ='ENG_OPS'!$E$20*(1-'IN_TECH'!$D$40) | F26: ='ENG_OPS'!$F$20*(1-'IN_TECH'!$D$40) | G26: ='ENG_OPS'!$G$20*(1-'IN_TECH'!$D$40) | H26: ='ENG_OPS'!$H$20*(1-'IN_TECH'!$D$40) | I26: ='ENG_OPS'!$I$20*(1-'IN_TECH'!$D$40) | J26: ='ENG_OPS'!$J$20*(1-'IN_TECH'!$D$40) | K26: ='ENG_OPS'!$K$20*(1-'IN_TECH'!$D$40) | L26: ='ENG_OPS'!$L$20*(1-'IN_TECH'!$D$40) | M26: ='ENG_OPS'!$M$20*(1-'IN_TECH'!$D$40) | N26: ='ENG_OPS'!$N$20*(1-'IN_TECH'!$D$40) | O26: ='ENG_OPS'!$O$20*(1-'IN_TECH'!$D$40) | P26: ='ENG_OPS'!$P$20*(1-'IN_TECH'!$D$40)
A27: خروجی ایستگاه ۲ (پس از خردایش) | B27: OPS.s2out | C27: تن | D27: ='ENG_OPS'!$D$26*(1-'IN_TECH'!$E$40) | E27: ='ENG_OPS'!$E$26*(1-'IN_TECH'!$E$40) | F27: ='ENG_OPS'!$F$26*(1-'IN_TECH'!$E$40) | G27: ='ENG_OPS'!$G$26*(1-'IN_TECH'!$E$40) | H27: ='ENG_OPS'!$H$26*(1-'IN_TECH'!$E$40) | I27: ='ENG_OPS'!$I$26*(1-'IN_TECH'!$E$40) | J27: ='ENG_OPS'!$J$26*(1-'IN_TECH'!$E$40) | K27: ='ENG_OPS'!$K$26*(1-'IN_TECH'!$E$40) | L27: ='ENG_OPS'!$L$26*(1-'IN_TECH'!$E$40) | M27: ='ENG_OPS'!$M$26*(1-'IN_TECH'!$E$40) | N27: ='ENG_OPS'!$N$26*(1-'IN_TECH'!$E$40) | O27: ='ENG_OPS'!$O$26*(1-'IN_TECH'!$E$40) | P27: ='ENG_OPS'!$P$26*(1-'IN_TECH'!$E$40)
A28: خمیر سرب (جریان تفکیک‌شده) | B28: OPS.paste | C28: تن | D28: ='ENG_OPS'!$D$27*'IN_TECH'!$D$27 | E28: ='ENG_OPS'!$E$27*'IN_TECH'!$D$27 | F28: ='ENG_OPS'!$F$27*'IN_TECH'!$D$27 | G28: ='ENG_OPS'!$G$27*'IN_TECH'!$D$27 | H28: ='ENG_OPS'!$H$27*'IN_TECH'!$D$27 | I28: ='ENG_OPS'!$I$27*'IN_TECH'!$D$27 | J28: ='ENG_OPS'!$J$27*'IN_TECH'!$D$27 | K28: ='ENG_OPS'!$K$27*'IN_TECH'!$D$27 | L28: ='ENG_OPS'!$L$27*'IN_TECH'!$D$27 | M28: ='ENG_OPS'!$M$27*'IN_TECH'!$D$27 | N28: ='ENG_OPS'!$N$27*'IN_TECH'!$D$27 | O28: ='ENG_OPS'!$O$27*'IN_TECH'!$D$27 | P28: ='ENG_OPS'!$P$27*'IN_TECH'!$D$27
A29: قطعات فلزی سربی (جریان تفکیک‌شده) | B29: OPS.metal | C29: تن | D29: ='ENG_OPS'!$D$27*'IN_TECH'!$D$28 | E29: ='ENG_OPS'!$E$27*'IN_TECH'!$D$28 | F29: ='ENG_OPS'!$F$27*'IN_TECH'!$D$28 | G29: ='ENG_OPS'!$G$27*'IN_TECH'!$D$28 | H29: ='ENG_OPS'!$H$27*'IN_TECH'!$D$28 | I29: ='ENG_OPS'!$I$27*'IN_TECH'!$D$28 | J29: ='ENG_OPS'!$J$27*'IN_TECH'!$D$28 | K29: ='ENG_OPS'!$K$27*'IN_TECH'!$D$28 | L29: ='ENG_OPS'!$L$27*'IN_TECH'!$D$28 | M29: ='ENG_OPS'!$M$27*'IN_TECH'!$D$28 | N29: ='ENG_OPS'!$N$27*'IN_TECH'!$D$28 | O29: ='ENG_OPS'!$O$27*'IN_TECH'!$D$28 | P29: ='ENG_OPS'!$P$27*'IN_TECH'!$D$28
A30: پلی‌پروپیلن (جریان تفکیک‌شده) | B30: OPS.pp | C30: تن | D30: ='ENG_OPS'!$D$27*'IN_TECH'!$D$29 | E30: ='ENG_OPS'!$E$27*'IN_TECH'!$D$29 | F30: ='ENG_OPS'!$F$27*'IN_TECH'!$D$29 | G30: ='ENG_OPS'!$G$27*'IN_TECH'!$D$29 | H30: ='ENG_OPS'!$H$27*'IN_TECH'!$D$29 | I30: ='ENG_OPS'!$I$27*'IN_TECH'!$D$29 | J30: ='ENG_OPS'!$J$27*'IN_TECH'!$D$29 | K30: ='ENG_OPS'!$K$27*'IN_TECH'!$D$29 | L30: ='ENG_OPS'!$L$27*'IN_TECH'!$D$29 | M30: ='ENG_OPS'!$M$27*'IN_TECH'!$D$29 | N30: ='ENG_OPS'!$N$27*'IN_TECH'!$D$29 | O30: ='ENG_OPS'!$O$27*'IN_TECH'!$D$29 | P30: ='ENG_OPS'!$P$27*'IN_TECH'!$D$29
A31: جداکننده و سایر پسماند (جریان تفکیک‌شده) | B31: OPS.res | C31: تن | D31: ='ENG_OPS'!$D$27*'IN_TECH'!$D$31 | E31: ='ENG_OPS'!$E$27*'IN_TECH'!$D$31 | F31: ='ENG_OPS'!$F$27*'IN_TECH'!$D$31 | G31: ='ENG_OPS'!$G$27*'IN_TECH'!$D$31 | H31: ='ENG_OPS'!$H$27*'IN_TECH'!$D$31 | I31: ='ENG_OPS'!$I$27*'IN_TECH'!$D$31 | J31: ='ENG_OPS'!$J$27*'IN_TECH'!$D$31 | K31: ='ENG_OPS'!$K$27*'IN_TECH'!$D$31 | L31: ='ENG_OPS'!$L$27*'IN_TECH'!$D$31 | M31: ='ENG_OPS'!$M$27*'IN_TECH'!$D$31 | N31: ='ENG_OPS'!$N$27*'IN_TECH'!$D$31 | O31: ='ENG_OPS'!$O$27*'IN_TECH'!$D$31 | P31: ='ENG_OPS'!$P$27*'IN_TECH'!$D$31
A32: الکترولیت تخلیه‌شده | B32: OPS.elec | C32: تن | D32: ='ENG_OPS'!$D$20*'IN_TECH'!$D$30 | E32: ='ENG_OPS'!$E$20*'IN_TECH'!$D$30 | F32: ='ENG_OPS'!$F$20*'IN_TECH'!$D$30 | G32: ='ENG_OPS'!$G$20*'IN_TECH'!$D$30 | H32: ='ENG_OPS'!$H$20*'IN_TECH'!$D$30 | I32: ='ENG_OPS'!$I$20*'IN_TECH'!$D$30 | J32: ='ENG_OPS'!$J$20*'IN_TECH'!$D$30 | K32: ='ENG_OPS'!$K$20*'IN_TECH'!$D$30 | L32: ='ENG_OPS'!$L$20*'IN_TECH'!$D$30 | M32: ='ENG_OPS'!$M$20*'IN_TECH'!$D$30 | N32: ='ENG_OPS'!$N$20*'IN_TECH'!$D$30 | O32: ='ENG_OPS'!$O$20*'IN_TECH'!$D$30 | P32: ='ENG_OPS'!$P$20*'IN_TECH'!$D$30
A33: خمیر سولفات‌زدایی‌شده | B33: OPS.paste_ds | C33: تن | D33: ='ENG_OPS'!$D$28*'IN_TECH'!$D$18*(1-'IN_TECH'!$F$40) | E33: ='ENG_OPS'!$E$28*'IN_TECH'!$D$18*(1-'IN_TECH'!$F$40) | F33: ='ENG_OPS'!$F$28*'IN_TECH'!$D$18*(1-'IN_TECH'!$F$40) | G33: ='ENG_OPS'!$G$28*'IN_TECH'!$D$18*(1-'IN_TECH'!$F$40) | H33: ='ENG_OPS'!$H$28*'IN_TECH'!$D$18*(1-'IN_TECH'!$F$40) | I33: ='ENG_OPS'!$I$28*'IN_TECH'!$D$18*(1-'IN_TECH'!$F$40) | J33: ='ENG_OPS'!$J$28*'IN_TECH'!$D$18*(1-'IN_TECH'!$F$40) | K33: ='ENG_OPS'!$K$28*'IN_TECH'!$D$18*(1-'IN_TECH'!$F$40) | L33: ='ENG_OPS'!$L$28*'IN_TECH'!$D$18*(1-'IN_TECH'!$F$40) | M33: ='ENG_OPS'!$M$28*'IN_TECH'!$D$18*(1-'IN_TECH'!$F$40) | N33: ='ENG_OPS'!$N$28*'IN_TECH'!$D$18*(1-'IN_TECH'!$F$40) | O33: ='ENG_OPS'!$O$28*'IN_TECH'!$D$18*(1-'IN_TECH'!$F$40) | P33: ='ENG_OPS'!$P$28*'IN_TECH'!$D$18*(1-'IN_TECH'!$F$40)
A34: سرب ورودی به کوره | B34: OPS.furnace_pb | C34: تن | D34: ='ENG_OPS'!$D$33*'IN_TECH'!$D$16+'ENG_OPS'!$D$29*'IN_TECH'!$D$17 | E34: ='ENG_OPS'!$E$33*'IN_TECH'!$D$16+'ENG_OPS'!$E$29*'IN_TECH'!$D$17 | F34: ='ENG_OPS'!$F$33*'IN_TECH'!$D$16+'ENG_OPS'!$F$29*'IN_TECH'!$D$17 | G34: ='ENG_OPS'!$G$33*'IN_TECH'!$D$16+'ENG_OPS'!$G$29*'IN_TECH'!$D$17 | H34: ='ENG_OPS'!$H$33*'IN_TECH'!$D$16+'ENG_OPS'!$H$29*'IN_TECH'!$D$17 | I34: ='ENG_OPS'!$I$33*'IN_TECH'!$D$16+'ENG_OPS'!$I$29*'IN_TECH'!$D$17 | J34: ='ENG_OPS'!$J$33*'IN_TECH'!$D$16+'ENG_OPS'!$J$29*'IN_TECH'!$D$17 | K34: ='ENG_OPS'!$K$33*'IN_TECH'!$D$16+'ENG_OPS'!$K$29*'IN_TECH'!$D$17 | L34: ='ENG_OPS'!$L$33*'IN_TECH'!$D$16+'ENG_OPS'!$L$29*'IN_TECH'!$D$17 | M34: ='ENG_OPS'!$M$33*'IN_TECH'!$D$16+'ENG_OPS'!$M$29*'IN_TECH'!$D$17 | N34: ='ENG_OPS'!$N$33*'IN_TECH'!$D$16+'ENG_OPS'!$N$29*'IN_TECH'!$D$17 | O34: ='ENG_OPS'!$O$33*'IN_TECH'!$D$16+'ENG_OPS'!$O$29*'IN_TECH'!$D$17 | P34: ='ENG_OPS'!$P$33*'IN_TECH'!$D$16+'ENG_OPS'!$P$29*'IN_TECH'!$D$17
A35: سرب خام خروجی کوره | B35: OPS.crude | C35: تن | D35: ='ENG_OPS'!$D$34*'IN_TECH'!$D$19*(1-'IN_TECH'!$G$40) | E35: ='ENG_OPS'!$E$34*'IN_TECH'!$D$19*(1-'IN_TECH'!$G$40) | F35: ='ENG_OPS'!$F$34*'IN_TECH'!$D$19*(1-'IN_TECH'!$G$40) | G35: ='ENG_OPS'!$G$34*'IN_TECH'!$D$19*(1-'IN_TECH'!$G$40) | H35: ='ENG_OPS'!$H$34*'IN_TECH'!$D$19*(1-'IN_TECH'!$G$40) | I35: ='ENG_OPS'!$I$34*'IN_TECH'!$D$19*(1-'IN_TECH'!$G$40) | J35: ='ENG_OPS'!$J$34*'IN_TECH'!$D$19*(1-'IN_TECH'!$G$40) | K35: ='ENG_OPS'!$K$34*'IN_TECH'!$D$19*(1-'IN_TECH'!$G$40) | L35: ='ENG_OPS'!$L$34*'IN_TECH'!$D$19*(1-'IN_TECH'!$G$40) | M35: ='ENG_OPS'!$M$34*'IN_TECH'!$D$19*(1-'IN_TECH'!$G$40) | N35: ='ENG_OPS'!$N$34*'IN_TECH'!$D$19*(1-'IN_TECH'!$G$40) | O35: ='ENG_OPS'!$O$34*'IN_TECH'!$D$19*(1-'IN_TECH'!$G$40) | P35: ='ENG_OPS'!$P$34*'IN_TECH'!$D$19*(1-'IN_TECH'!$G$40)
A36: سرب تصفیه‌شده | B36: OPS.refined | C36: تن | D36: ='ENG_OPS'!$D$35*'IN_TECH'!$D$20*(1-'IN_TECH'!$H$40) | E36: ='ENG_OPS'!$E$35*'IN_TECH'!$D$20*(1-'IN_TECH'!$H$40) | F36: ='ENG_OPS'!$F$35*'IN_TECH'!$D$20*(1-'IN_TECH'!$H$40) | G36: ='ENG_OPS'!$G$35*'IN_TECH'!$D$20*(1-'IN_TECH'!$H$40) | H36: ='ENG_OPS'!$H$35*'IN_TECH'!$D$20*(1-'IN_TECH'!$H$40) | I36: ='ENG_OPS'!$I$35*'IN_TECH'!$D$20*(1-'IN_TECH'!$H$40) | J36: ='ENG_OPS'!$J$35*'IN_TECH'!$D$20*(1-'IN_TECH'!$H$40) | K36: ='ENG_OPS'!$K$35*'IN_TECH'!$D$20*(1-'IN_TECH'!$H$40) | L36: ='ENG_OPS'!$L$35*'IN_TECH'!$D$20*(1-'IN_TECH'!$H$40) | M36: ='ENG_OPS'!$M$35*'IN_TECH'!$D$20*(1-'IN_TECH'!$H$40) | N36: ='ENG_OPS'!$N$35*'IN_TECH'!$D$20*(1-'IN_TECH'!$H$40) | O36: ='ENG_OPS'!$O$35*'IN_TECH'!$D$20*(1-'IN_TECH'!$H$40) | P36: ='ENG_OPS'!$P$35*'IN_TECH'!$D$20*(1-'IN_TECH'!$H$40)
A38: ج) محصولات قابل فروش
